Workbook

Sheet KORPORAT KANWIL
D1: PT JAMKRINDO KANWIL SURABAYA
D2: LABA RUGI RKA TAHUN 2026
O4: =#REF! -> #REF!
D5: URAIAN | F5: KORPORAT WILAYAH SURABAYA | L5: REALISASI KORPORAT KANWIL SURABAYA | P5: %
F6: KUR | G6: PEN | H6: KBG/SURETYSHIP | I6: KONSUMTIF | J6: PRODUKTIF | K6: TOTAL | L6: KUR | M6: PEN | N6: NON KUR | O6: TOTAL | P6: %
C8: X1 | D8: VOLUME | F8: =KANWIL!F8+SURABAYA!F8+KEDIRI!F8+MALANG!F8+MADIUN!F8+BANYUWANGI!F8 -> 29155734228583 | G8: =KANWIL!G8+SURABAYA!G8+KEDIRI!G8+MALANG!G8+MADIUN!G8+BANYUWANGI!G8 -> 0 | H8: =KANWIL!H8+SURABAYA!H8+KEDIRI!H8+MALANG!H8+MADIUN!H8+BANYUWANGI!H8 -> 6633105465239 | I8: =KANWIL!I8+SURABAYA!I8+KEDIRI!I8+MALANG!I8+MADIUN!I8+BANYUWANGI!I8 -> 2866310409375 | J8: =KANWIL!J8+SURABAYA!J8+KEDIRI!J8+MALANG!J8+MADIUN!J8+BANYUWANGI!J8 -> 5889752816264 | K8: =SUM(F8:J8) -> 44544902919461 | L8: =KANWIL!L8+SURABAYA!L8+KEDIRI!L8+MALANG!L8+MADIUN!L8+BANYUWANGI!L8 -> 2.1418335e+13 | M8: =KANWIL!M8+SURABAYA!M8+KEDIRI!M8+MALANG!M8+MADIUN!M8+BANYUWANGI!M8 -> 0 | N8: =KANWIL!N8+SURABAYA!N8+KEDIRI!N8+MALANG!N8+MADIUN!N8+BANYUWANGI!N8 -> 5.3925176e+12 | O8: =SUM(L8:N8) -> 2.6810852e+13 | P8: =O8/K8 -> 0.60188373
C10: X2 | D10: PENDAPATAN PENJAMINAN
A11: 7 | B11: 8 | E11: Imbal Jasa Penjaminan Bruto | F11: =KANWIL!F11+SURABAYA!F11+KEDIRI!F11+MALANG!F11+MADIUN!F11+BANYUWANGI!F11 -> 1054205218156 | G11: =KANWIL!G11+SURABAYA!G11+KEDIRI!G11+MALANG!G11+MADIUN!G11+BANYUWANGI!G11 -> 0 | H11: =KANWIL!H11+SURABAYA!H11+KEDIRI!H11+MALANG!H11+MADIUN!H11+BANYUWANGI!H11 -> 21616987266 | I11: =KANWIL!I11+SURABAYA!I11+KEDIRI!I11+MALANG!I11+MADIUN!I11+BANYUWANGI!I11 -> 27821631504 | J11: =KANWIL!J11+SURABAYA!J11+KEDIRI!J11+MALANG!J11+MADIUN!J11+BANYUWANGI!J11 -> 122415438555 | K11: =SUM(F11:J11) -> 1226059275481 | L11: =KANWIL!L11+SURABAYA!L11+KEDIRI!L11+MALANG!L11+MADIUN!L11+BANYUWANGI!L11 -> 5.455123e+11 | M11: =KANWIL!M11+SURABAYA!M11+KEDIRI!M11+MALANG!M11+MADIUN!M11+BANYUWANGI!M11 -> 400000 | N11: =KANWIL!N11+SURABAYA!N11+KEDIRI!N11+MALANG!N11+MADIUN!N11+BANYUWANGI!N11 -> 2.0832822e+11 | O11: =SUM(L11:N11) -> 7.5384092e+11 | P11: =O11/K11 -> 0.61484867
A12: 12 | B12: 10 | E12: Restitusi penjaminan kredit | F12: =KANWIL!F12+SURABAYA!F12+KEDIRI!F12+MALANG!F12+MADIUN!F12+BANYUWANGI!F12 -> 0 | G12: =KANWIL!G12+SURABAYA!G12+KEDIRI!G12+MALANG!G12+MADIUN!G12+BANYUWANGI!G12 -> 0 | H12: =KANWIL!H12+SURABAYA!H12+KEDIRI!H12+MALANG!H12+MADIUN!H12+BANYUWANGI!H12 -> 0 | I12: =KANWIL!I12+SURABAYA!I12+KEDIRI!I12+MALANG!I12+MADIUN!I12+BANYUWANGI!I12 -> 0 | J12: =KANWIL!J12+SURABAYA!J12+KEDIRI!J12+MALANG!J12+MADIUN!J12+BANYUWANGI!J12 -> 0 | K12: =SUM(F12:J12) -> 0 | L12: =KANWIL!L12+SURABAYA!L12+KEDIRI!L12+MALANG!L12+MADIUN!L12+BANYUWANGI!L12 -> 0 | M12: =KANWIL!M12+SURABAYA!M12+KEDIRI!M12+MALANG!M12+MADIUN!M12+BANYUWANGI!M12 -> 0 | N12: =KANWIL!N12+SURABAYA!N12+KEDIRI!N12+MALANG!N12+MADIUN!N12+BANYUWANGI!N12 -> 0 | O12: =SUM(L12:N12) -> 0 | P12: 0
A13: 9 | B13: 9 | E13: Premi Penjaminan Ulang | F13: =KANWIL!F13+SURABAYA!F13+KEDIRI!F13+MALANG!F13+MADIUN!F13+BANYUWANGI!F13 -> 94927046114 | G13: =KANWIL!G13+SURABAYA!G13+KEDIRI!G13+MALANG!G13+MADIUN!G13+BANYUWANGI!G13 -> 0 | H13: =KANWIL!H13+SURABAYA!H13+KEDIRI!H13+MALANG!H13+MADIUN!H13+BANYUWANGI!H13 -> 2624698636 | I13: =KANWIL!I13+SURABAYA!I13+KEDIRI!I13+MALANG!I13+MADIUN!I13+BANYUWANGI!I13 -> 4151753688 | J13: =KANWIL!J13+SURABAYA!J13+KEDIRI!J13+MALANG!J13+MADIUN!J13+BANYUWANGI!J13 -> 72171043143 | K13: =SUM(F13:J13) -> 173874541581 | L13: =KANWIL!L13+SURABAYA!L13+KEDIRI!L13+MALANG!L13+MADIUN!L13+BANYUWANGI!L13 -> 5.776021e+10 | M13: =KANWIL!M13+SURABAYA!M13+KEDIRI!M13+MALANG!M13+MADIUN!M13+BANYUWANGI!M13 -> 0 | N13: =KANWIL!N13+SURABAYA!N13+KEDIRI!N13+MALANG!N13+MADIUN!N13+BANYUWANGI!N13 -> 2.6754792e+10 | O13: =SUM(L13:N13) -> 8.4515001e+10 | P13: =O13/K13 -> 0.48606887
C14: Y2 | E14: IMBAL JASA PENJAMINAN BERSIH | F14: =F11-F12-F13 -> 959278172042 | G14: =G11-G12-G13 -> 0 | H14: =H11-H12-H13 -> 18992288630 | I14: =I11-I12-I13 -> 23669877816 | J14: =J11-J12-J13 -> 50244395412 | K14: =K11-K12-K13 -> 1052184733900 | L14: =L11-L12-L13 -> 4.877521e+11 | M14: =M11-M12-M13 -> 400000 | ... O14: =O11-O12-O13 -> 6.6932592e+11 | P14: =O14/K14 -> 0.63612966
C16: X2 | D16: BEBAN KLAIM
A17: 22 | B17: 13 | E17: Beban Klaim | F17: =KANWIL!F17+SURABAYA!F17+KEDIRI!F17+MALANG!F17+MADIUN!F17+BANYUWANGI!F17 -> 809802922564 | G17: =KANWIL!G17+SURABAYA!G17+KEDIRI!G17+MALANG!G17+MADIUN!G17+BANYUWANGI!G17 -> 34965416239 | H17: =KANWIL!H17+SURABAYA!H17+KEDIRI!H17+MALANG!H17+MADIUN!H17+BANYUWANGI!H17 -> 5658069138 | I17: =KANWIL!I17+SURABAYA!I17+KEDIRI!I17+MALANG!I17+MADIUN!I17+BANYUWANGI!I17 -> 9169963227 | J17: =KANWIL!J17+SURABAYA!J17+KEDIRI!J17+MALANG!J17+MADIUN!J17+BANYUWANGI!J17 -> 102940478187 | K17: =SUM(F17:J17) -> 962536849355 | L17: =KANWIL!L17+SURABAYA!L17+KEDIRI!L17+MALANG!L17+MADIUN!L17+BANYUWANGI!L17 -> 3.3259949e+11 | M17: =KANWIL!M17+SURABAYA!M17+KEDIRI!M17+MALANG!M17+MADIUN!M17+BANYUWANGI!M17 -> 6.5023855e+09 | N17: =KANWIL!N17+SURABAYA!N17+KEDIRI!N17+MALANG!N17+MADIUN!N17+BANYUWANGI!N17 -> 1.8209554e+11 | O17: =SUM(L17:N17) -> 5.2119741e+11 | P17: =O17/K17 -> 0.54148307
A18: 24 | B18: 14 | E18: Kenaikan (Penurunan) Cadangan Klaim | F18: =KANWIL!F18+SURABAYA!F18+KEDIRI!F18+MALANG!F18+MADIUN!F18+BANYUWANGI!F18 -> 9715485499 | G18: =KANWIL!G18+SURABAYA!G18+KEDIRI!G18+MALANG!G18+MADIUN!G18+BANYUWANGI!G18 -> -10323848200 | H18: =KANWIL!H18+SURABAYA!H18+KEDIRI!H18+MALANG!H18+MADIUN!H18+BANYUWANGI!H18 -> 677983388 | I18: =KANWIL!I18+SURABAYA!I18+KEDIRI!I18+MALANG!I18+MADIUN!I18+BANYUWANGI!I18 -> 397223586 | J18: =KANWIL!J18+SURABAYA!J18+KEDIRI!J18+MALANG!J18+MADIUN!J18+BANYUWANGI!J18 -> 31382109977 | K18: =SUM(F18:J18) -> 31848954250 | L18: =KANWIL!L18+SURABAYA!L18+KEDIRI!L18+MALANG!L18+MADIUN!L18+BANYUWANGI!L18 -> 7.4728788e+10 | M18: =KANWIL!M18+SURABAYA!M18+KEDIRI!M18+MALANG!M18+MADIUN!M18+BANYUWANGI!M18 -> -9.0317836e+09 | N18: =KANWIL!N18+SURABAYA!N18+KEDIRI!N18+MALANG!N18+MADIUN!N18+BANYUWANGI!N18 -> 1.2135773e+10 | O18: =SUM(L18:N18) -> 7.7832777e+10 | P18: =O18/K18 -> 2.4438095
A19: 32 | B19: 15 | E19: Pendapatan Subrogasi | F19: =KANWIL!F19+SURABAYA!F19+KEDIRI!F19+MALANG!F19+MADIUN!F19+BANYUWANGI!F19 -> 208858906675 | G19: =KANWIL!G19+SURABAYA!G19+KEDIRI!G19+MALANG!G19+MADIUN!G19+BANYUWANGI!G19 -> 34248988772 | H19: =KANWIL!H19+SURABAYA!H19+KEDIRI!H19+MALANG!H19+MADIUN!H19+BANYUWANGI!H19 -> 147999934 | I19: =KANWIL!I19+SURABAYA!I19+KEDIRI!I19+MALANG!I19+MADIUN!I19+BANYUWANGI!I19 -> 301999866 | J19: =KANWIL!J19+SURABAYA!J19+KEDIRI!J19+MALANG!J19+MADIUN!J19+BANYUWANGI!J19 -> 83496959312 | K19: =SUM(F19:J19) -> 327054854559 | L19: =KANWIL!L19+SURABAYA!L19+KEDIRI!L19+MALANG!L19+MADIUN!L19+BANYUWANGI!L19 -> 1.0831009e+11 | M19: =KANWIL!M19+SURABAYA!M19+KEDIRI!M19+MALANG!M19+MADIUN!M19+BANYUWANGI!M19 -> 1.2937903e+10 | N19: =KANWIL!N19+SURABAYA!N19+KEDIRI!N19+MALANG!N19+MADIUN!N19+BANYUWANGI!N19 -> 4.0738256e+10 | O19: =SUM(L19:N19) -> 1.6198625e+11 | P19: =O19/K19 -> 0.49528772
A20: 37 | B20: 16 | E20: Beban Komisi Netto | F20: =KANWIL!F20+SURABAYA!F20+KEDIRI!F20+MALANG!F20+MADIUN!F20+BANYUWANGI!F20 -> 14979526236 | G20: =KANWIL!G20+SURABAYA!G20+KEDIRI!G20+MALANG!G20+MADIUN!G20+BANYUWANGI!G20 -> 0 | H20: =KANWIL!H20+SURABAYA!H20+KEDIRI!H20+MALANG!H20+MADIUN!H20+BANYUWANGI!H20 -> 456146159 | I20: =KANWIL!I20+SURABAYA!I20+KEDIRI!I20+MALANG!I20+MADIUN!I20+BANYUWANGI!I20 -> 634577379 | J20: =KANWIL!J20+SURABAYA!J20+KEDIRI!J20+MALANG!J20+MADIUN!J20+BANYUWANGI!J20 -> 11015252139 | K20: =SUM(F20:J20) -> 27085501913 | L20: =KANWIL!L20+SURABAYA!L20+KEDIRI!L20+MALANG!L20+MADIUN!L20+BANYUWANGI!L20 -> 9.4954242e+09 | M20: =KANWIL!M20+SURABAYA!M20+KEDIRI!M20+MALANG!M20+MADIUN!M20+BANYUWANGI!M20 -> 0 | N20: =KANWIL!N20+SURABAYA!N20+KEDIRI!N20+MALANG!N20+MADIUN!N20+BANYUWANGI!N20 -> 3.711802e+09 | O20: =SUM(L20:N20) -> 1.3207226e+10 | P20: =O20/K20 -> 0.48761239
C21: Y2 | E21: JUMLAH BEBAN KLAIM | F21: =F17+F18-F19-F20 -> 595679975152 | G21: =G17+G18-G19-G20 -> -9607420733 | H21: =H17+H18-H19-H20 -> 5731906433 | I21: =I17+I18-I19-I20 -> 8630609568 | J21: =J17+J18-J19-J20 -> 39810376713 | K21: =K17+K18-K19-K20 -> 640245447133 | L21: =L17+L18-L19-L20 -> 2.8952276e+11 | M21: =M17+M18-M19-M20 -> -1.5467301e+10 | ... O21: =O17+O18-O19-O20 -> 4.2383671e+11 | P21: =O21/K21 -> 0.66199098
C23: X1 | D23: PENJAMINAN BERSIH | F23: =F14-F21 -> 363598196890 | G23: =G14-G21 -> 9607420733 | H23: =H14-H21 -> 13260382197 | I23: =I14-I21 -> 15039268248 | J23: =J14-J21 -> 10434018699 | K23: =K14-K21 -> 411939286767 | L23: =L14-L21 -> 1.9822934e+11 | M23: =M14-M21 -> 1.5467701e+10 | ... O23: =O14-O21 -> 2.4548921e+11 | P23: =O23/K23 -> 0.59593542
B25: 19 | C25: X1 | D25: PENDAPATAN INVESTASI BERSIH | F25: 0 | G25: 0 | H25: 0 | I25: 0 | J25: 0 | K25: 0 | L25: 0 | M25: 0 | N25: 0 | O25: 0 | P25: 0
C27: X1 | D27: BEBAN USAHA
C28: X2 | E28: BEBAN KARYAWAN
A29: 94 | E29: Beban gaji karyawan | F29: =KANWIL!F29+SURABAYA!F29+KEDIRI!F29+MALANG!F29+MADIUN!F29+BANYUWANGI!F29 -> 8079970152 | G29: =KANWIL!G29+SURABAYA!G29+KEDIRI!G29+MALANG!G29+MADIUN!G29+BANYUWANGI!G29 -> 0 | H29: =KANWIL!H29+SURABAYA!H29+KEDIRI!H29+MALANG!H29+MADIUN!H29+BANYUWANGI!H29 -> 165683692 | I29: =KANWIL!I29+SURABAYA!I29+KEDIRI!I29+MALANG!I29+MADIUN!I29+BANYUWANGI!I29 -> 213239272 | J29: =KANWIL!J29+SURABAYA!J29+KEDIRI!J29+MALANG!J29+MADIUN!J29+BANYUWANGI!J29 -> 938254784 | K29: =SUM(F29:J29) -> 9397147900 | L29: =KANWIL!L29+SURABAYA!L29+KEDIRI!L29+MALANG!L29+MADIUN!L29+BANYUWANGI!L29 -> 3.8425372e+09 | M29: =KANWIL!M29+SURABAYA!M29+KEDIRI!M29+MALANG!M29+MADIUN!M29+BANYUWANGI!M29 -> 0 | N29: =KANWIL!N29+SURABAYA!N29+KEDIRI!N29+MALANG!N29+MADIUN!N29+BANYUWANGI!N29 -> 1.6862537e+09 | O29: =SUM(L29:N29) -> 5.528791e+09 | P29: =O29/K29 -> 0.58834777
A30: 95 | E30: Beban lembur karyawan | F30: =KANWIL!F30+SURABAYA!F30+KEDIRI!F30+MALANG!F30+MADIUN!F30+BANYUWANGI!F30 -> 252985625 | G30: =KANWIL!G30+SURABAYA!G30+KEDIRI!G30+MALANG!G30+MADIUN!G30+BANYUWANGI!G30 -> 0 | H30: =KANWIL!H30+SURABAYA!H30+KEDIRI!H30+MALANG!H30+MADIUN!H30+BANYUWANGI!H30 -> 5187593 | I30: =KANWIL!I30+SURABAYA!I30+KEDIRI!I30+MALANG!I30+MADIUN!I30+BANYUWANGI!I30 -> 6676569 | J30: =KANWIL!J30+SURABAYA!J30+KEDIRI!J30+MALANG!J30+MADIUN!J30+BANYUWANGI!J30 -> 29376961 | K30: =SUM(F30:J30) -> 294226748 | L30: =KANWIL!L30+SURABAYA!L30+KEDIRI!L30+MALANG!L30+MADIUN!L30+BANYUWANGI!L30 -> 1.0881745e+08 | M30: =KANWIL!M30+SURABAYA!M30+KEDIRI!M30+MALANG!M30+MADIUN!M30+BANYUWANGI!M30 -> 0 | N30: =KANWIL!N30+SURABAYA!N30+KEDIRI!N30+MALANG!N30+MADIUN!N30+BANYUWANGI!N30 -> 46610415 | O30: =SUM(L30:N30) -> 1.5542786e+08 | P30: =O30/K30 -> 0.52825877
A31: 96 | E31: Beban asuransi kesehatan karyawan | F31: =KANWIL!F31+SURABAYA!F31+KEDIRI!F31+MALANG!F31+MADIUN!F31+BANYUWANGI!F31 -> 1203089015 | G31: =KANWIL!G31+SURABAYA!G31+KEDIRI!G31+MALANG!G31+MADIUN!G31+BANYUWANGI!G31 -> 0 | H31: =KANWIL!H31+SURABAYA!H31+KEDIRI!H31+MALANG!H31+MADIUN!H31+BANYUWANGI!H31 -> 24669920 | I31: =KANWIL!I31+SURABAYA!I31+KEDIRI!I31+MALANG!I31+MADIUN!I31+BANYUWANGI!I31 -> 31750838 | J31: =KANWIL!J31+SURABAYA!J31+KEDIRI!J31+MALANG!J31+MADIUN!J31+BANYUWANGI!J31 -> 139703984 | K31: =SUM(F31:J31) -> 1399213757 | L31: =KANWIL!L31+SURABAYA!L31+KEDIRI!L31+MALANG!L31+MADIUN!L31+BANYUWANGI!L31 -> 32771149 | M31: =KANWIL!M31+SURABAYA!M31+KEDIRI!M31+MALANG!M31+MADIUN!M31+BANYUWANGI!M31 -> 0 | N31: =KANWIL!N31+SURABAYA!N31+KEDIRI!N31+MALANG!N31+MADIUN!N31+BANYUWANGI!N31 -> 13237851 | O31: =SUM(L31:N31) -> 46009000 | P31: =O31/K31 -> 0.032882038
A32: 97 | E32: Beban asuransi jiwa karyawan | F32: =KANWIL!F32+SURABAYA!F32+KEDIRI!F32+MALANG!F32+MADIUN!F32+BANYUWANGI!F32 -> 55120357 | G32: =KANWIL!G32+SURABAYA!G32+KEDIRI!G32+MALANG!G32+MADIUN!G32+BANYUWANGI!G32 -> 0 | H32: =KANWIL!H32+SURABAYA!H32+KEDIRI!H32+MALANG!H32+MADIUN!H32+BANYUWANGI!H32 -> 1130269 | I32: =KANWIL!I32+SURABAYA!I32+KEDIRI!I32+MALANG!I32+MADIUN!I32+BANYUWANGI!I32 -> 1454687 | J32: =KANWIL!J32+SURABAYA!J32+KEDIRI!J32+MALANG!J32+MADIUN!J32+BANYUWANGI!J32 -> 6400635 | K32: =SUM(F32:J32) -> 64105948 | L32: =KANWIL!L32+SURABAYA!L32+KEDIRI!L32+MALANG!L32+MADIUN!L32+BANYUWANGI!L32 -> 0 | M32: =KANWIL!M32+SURABAYA!M32+KEDIRI!M32+MALANG!M32+MADIUN!M32+BANYUWANGI!M32 -> 0 | N32: =KANWIL!N32+SURABAYA!N32+KEDIRI!N32+MALANG!N32+MADIUN!N32+BANYUWANGI!N32 -> 0 | O32: =SUM(L32:N32) -> 0 | P32: =O32/K32 -> 0
A33: 100 | E33: Beban dana pensiun | F33: =KANWIL!F33+SURABAYA!F33+KEDIRI!F33+MALANG!F33+MADIUN!F33+BANYUWANGI!F33 -> 873635539 | G33: =KANWIL!G33+SURABAYA!G33+KEDIRI!G33+MALANG!G33+MADIUN!G33+BANYUWANGI!G33 -> 0 | H33: =KANWIL!H33+SURABAYA!H33+KEDIRI!H33+MALANG!H33+MADIUN!H33+BANYUWANGI!H33 -> 17914319 | I33: =KANWIL!I33+SURABAYA!I33+KEDIRI!I33+MALANG!I33+MADIUN!I33+BANYUWANGI!I33 -> 23056200 | J33: =KANWIL!J33+SURABAYA!J33+KEDIRI!J33+MALANG!J33+MADIUN!J33+BANYUWANGI!J33 -> 101447493 | K33: =SUM(F33:J33) -> 1016053551 | L33: =KANWIL!L33+SURABAYA!L33+KEDIRI!L33+MALANG!L33+MADIUN!L33+BANYUWANGI!L33 -> 0 | M33: =KANWIL!M33+SURABAYA!M33+KEDIRI!M33+MALANG!M33+MADIUN!M33+BANYUWANGI!M33 -> 0 | N33: =KANWIL!N33+SURABAYA!N33+KEDIRI!N33+MALANG!N33+MADIUN!N33+BANYUWANGI!N33 -> 0 | O33: =SUM(L33:N33) -> 0 | P33: =O33/K33 -> 0
A34: 101 | E34: Beban kompensasi kinerja karyawan | F34: =KANWIL!F34+SURABAYA!F34+KEDIRI!F34+MALANG!F34+MADIUN!F34+BANYUWANGI!F34 -> 9945044587 | G34: =KANWIL!G34+SURABAYA!G34+KEDIRI!G34+MALANG!G34+MADIUN!G34+BANYUWANGI!G34 -> 0 | H34: =KANWIL!H34+SURABAYA!H34+KEDIRI!H34+MALANG!H34+MADIUN!H34+BANYUWANGI!H34 -> 203927943 | I34: =KANWIL!I34+SURABAYA!I34+KEDIRI!I34+MALANG!I34+MADIUN!I34+BANYUWANGI!I34 -> 262460630 | J34: =KANWIL!J34+SURABAYA!J34+KEDIRI!J34+MALANG!J34+MADIUN!J34+BANYUWANGI!J34 -> 1154829224 | K34: =SUM(F34:J34) -> 11566262384 | L34: =KANWIL!L34+SURABAYA!L34+KEDIRI!L34+MALANG!L34+MADIUN!L34+BANYUWANGI!L34 -> 4.9904913e+09 | M34: =KANWIL!M34+SURABAYA!M34+KEDIRI!M34+MALANG!M34+MADIUN!M34+BANYUWANGI!M34 -> 0 | N34: =KANWIL!N34+SURABAYA!N34+KEDIRI!N34+MALANG!N34+MADIUN!N34+BANYUWANGI!N34 -> 2.1914926e+09 | O34: =SUM(L34:N34) -> 7.181984e+09 | P34: =O34/K34 -> 0.62094251
A35: 102 | E35: Biaya jasa kini karyawan | F35: =KANWIL!F35+SURABAYA!F35+KEDIRI!F35+MALANG!F35+MADIUN!F35+BANYUWANGI!F35 -> 0 | G35: =KANWIL!G35+SURABAYA!G35+KEDIRI!G35+MALANG!G35+MADIUN!G35+BANYUWANGI!G35 -> 0 | H35: =KANWIL!H35+SURABAYA!H35+KEDIRI!H35+MALANG!H35+MADIUN!H35+BANYUWANGI!H35 -> 0 | I35: =KANWIL!I35+SURABAYA!I35+KEDIRI!I35+MALANG!I35+MADIUN!I35+BANYUWANGI!I35 -> 0 | J35: =KANWIL!J35+SURABAYA!J35+KEDIRI!J35+MALANG!J35+MADIUN!J35+BANYUWANGI!J35 -> 0 | K35: =SUM(F35:J35) -> 0 | L35: =KANWIL!L35+SURABAYA!L35+KEDIRI!L35+MALANG!L35+MADIUN!L35+BANYUWANGI!L35 -> 0 | M35: =KANWIL!M35+SURABAYA!M35+KEDIRI!M35+MALANG!M35+MADIUN!M35+BANYUWANGI!M35 -> 0 | N35: =KANWIL!N35+SURABAYA!N35+KEDIRI!N35+MALANG!N35+MADIUN!N35+BANYUWANGI!N35 -> 0 | O35: =SUM(L35:N35) -> 0 | P35: 0
A36: 103 | E36: Biaya jasa lalu karyawan | F36: =KANWIL!F36+SURABAYA!F36+KEDIRI!F36+MALANG!F36+MADIUN!F36+BANYUWANGI!F36 -> 0 | G36: =KANWIL!G36+SURABAYA!G36+KEDIRI!G36+MALANG!G36+MADIUN!G36+BANYUWANGI!G36 -> 0 | H36: =KANWIL!H36+SURABAYA!H36+KEDIRI!H36+MALANG!H36+MADIUN!H36+BANYUWANGI!H36 -> 0 | I36: =KANWIL!I36+SURABAYA!I36+KEDIRI!I36+MALANG!I36+MADIUN!I36+BANYUWANGI!I36 -> 0 | J36: =KANWIL!J36+SURABAYA!J36+KEDIRI!J36+MALANG!J36+MADIUN!J36+BANYUWANGI!J36 -> 0 | K36: =SUM(F36:J36) -> 0 | L36: =KANWIL!L36+SURABAYA!L36+KEDIRI!L36+MALANG!L36+MADIUN!L36+BANYUWANGI!L36 -> 0 | M36: =KANWIL!M36+SURABAYA!M36+KEDIRI!M36+MALANG!M36+MADIUN!M36+BANYUWANGI!M36 -> 0 | N36: =KANWIL!N36+SURABAYA!N36+KEDIRI!N36+MALANG!N36+MADIUN!N36+BANYUWANGI!N36 -> 0 | O36: =SUM(L36:N36) -> 0 | P36: 0
A37: 104 | E37: Bunga atas imbalan pasca kerja karyawan | F37: =KANWIL!F37+SURABAYA!F37+KEDIRI!F37+MALANG!F37+MADIUN!F37+BANYUWANGI!F37 -> 1321025775 | G37: =KANWIL!G37+SURABAYA!G37+KEDIRI!G37+MALANG!G37+MADIUN!G37+BANYUWANGI!G37 -> 0 | H37: =KANWIL!H37+SURABAYA!H37+KEDIRI!H37+MALANG!H37+MADIUN!H37+BANYUWANGI!H37 -> 27088272 | I37: =KANWIL!I37+SURABAYA!I37+KEDIRI!I37+MALANG!I37+MADIUN!I37+BANYUWANGI!I37 -> 34863319 | J37: =KANWIL!J37+SURABAYA!J37+KEDIRI!J37+MALANG!J37+MADIUN!J37+BANYUWANGI!J37 -> 153398927 | K37: =SUM(F37:J37) -> 1536376293 | L37: =KANWIL!L37+SURABAYA!L37+KEDIRI!L37+MALANG!L37+MADIUN!L37+BANYUWANGI!L37 -> 0 | M37: =KANWIL!M37+SURABAYA!M37+KEDIRI!M37+MALANG!M37+MADIUN!M37+BANYUWANGI!M37 -> 0 | N37: =KANWIL!N37+SURABAYA!N37+KEDIRI!N37+MALANG!N37+MADIUN!N37+BANYUWANGI!N37 -> 0 | O37: =SUM(L37:N37) -> 0 | P37: =O37/K37 -> 0
A38: 105 | E38: Beban BPJS kesehatan karyawan | F38: =KANWIL!F38+SURABAYA!F38+KEDIRI!F38+MALANG!F38+MADIUN!F38+BANYUWANGI!F38 -> 335276936 | G38: =KANWIL!G38+SURABAYA!G38+KEDIRI!G38+MALANG!G38+MADIUN!G38+BANYUWANGI!G38 -> 0 | H38: =KANWIL!H38+SURABAYA!H38+KEDIRI!H38+MALANG!H38+MADIUN!H38+BANYUWANGI!H38 -> 6875015 | I38: =KANWIL!I38+SURABAYA!I38+KEDIRI!I38+MALANG!I38+MADIUN!I38+BANYUWANGI!I38 -> 8848326 | J38: =KANWIL!J38+SURABAYA!J38+KEDIRI!J38+MALANG!J38+MADIUN!J38+BANYUWANGI!J38 -> 38932718 | K38: =SUM(F38:J38) -> 389932995 | L38: =KANWIL!L38+SURABAYA!L38+KEDIRI!L38+MALANG!L38+MADIUN!L38+BANYUWANGI!L38 -> 0 | M38: =KANWIL!M38+SURABAYA!M38+KEDIRI!M38+MALANG!M38+MADIUN!M38+BANYUWANGI!M38 -> 0 | N38: =KANWIL!N38+SURABAYA!N38+KEDIRI!N38+MALANG!N38+MADIUN!N38+BANYUWANGI!N38 -> 0 | O38: =SUM(L38:N38) -> 0 | P38: =O38/K38 -> 0
A39: 106 | E39: Beban BPJS jaminan hari tua karyawan | F39: =KANWIL!F39+SURABAYA!F39+KEDIRI!F39+MALANG!F39+MADIUN!F39+BANYUWANGI!F39 -> 475623528 | G39: =KANWIL!G39+SURABAYA!G39+KEDIRI!G39+MALANG!G39+MADIUN!G39+BANYUWANGI!G39 -> 0 | H39: =KANWIL!H39+SURABAYA!H39+KEDIRI!H39+MALANG!H39+MADIUN!H39+BANYUWANGI!H39 -> 9752891 | I39: =KANWIL!I39+SURABAYA!I39+KEDIRI!I39+MALANG!I39+MADIUN!I39+BANYUWANGI!I39 -> 12552226 | J39: =KANWIL!J39+SURABAYA!J39+KEDIRI!J39+MALANG!J39+MADIUN!J39+BANYUWANGI!J39 -> 55229913 | K39: =SUM(F39:J39) -> 553158558 | L39: =KANWIL!L39+SURABAYA!L39+KEDIRI!L39+MALANG!L39+MADIUN!L39+BANYUWANGI!L39 -> 0 | M39: =KANWIL!M39+SURABAYA!M39+KEDIRI!M39+MALANG!M39+MADIUN!M39+BANYUWANGI!M39 -> 0 | N39: =KANWIL!N39+SURABAYA!N39+KEDIRI!N39+MALANG!N39+MADIUN!N39+BANYUWANGI!N39 -> 0 | O39: =SUM(L39:N39) -> 0 | P39: =O39/K39 -> 0
A40: 107 | E40: Beban BPJS jaminan kecelakaan kerja dan jaminan kematian karyawan | F40: =KANWIL!F40+SURABAYA!F40+KEDIRI!F40+MALANG!F40+MADIUN!F40+BANYUWANGI!F40 -> 69028547 | G40: =KANWIL!G40+SURABAYA!G40+KEDIRI!G40+MALANG!G40+MADIUN!G40+BANYUWANGI!G40 -> 0 | H40: =KANWIL!H40+SURABAYA!H40+KEDIRI!H40+MALANG!H40+MADIUN!H40+BANYUWANGI!H40 -> 1415464 | I40: =KANWIL!I40+SURABAYA!I40+KEDIRI!I40+MALANG!I40+MADIUN!I40+BANYUWANGI!I40 -> 1821739 | J40: =KANWIL!J40+SURABAYA!J40+KEDIRI!J40+MALANG!J40+MADIUN!J40+BANYUWANGI!J40 -> 8015669 | K40: =SUM(F40:J40) -> 80281419 | L40: =KANWIL!L40+SURABAYA!L40+KEDIRI!L40+MALANG!L40+MADIUN!L40+BANYUWANGI!L40 -> 0 | M40: =KANWIL!M40+SURABAYA!M40+KEDIRI!M40+MALANG!M40+MADIUN!M40+BANYUWANGI!M40 -> 0 | N40: =KANWIL!N40+SURABAYA!N40+KEDIRI!N40+MALANG!N40+MADIUN!N40+BANYUWANGI!N40 -> 0 | O40: =SUM(L40:N40) -> 0 | P40: =O40/K40 -> 0
A41: 108 | E41: Beban BPJS jaminan pensiun karyawan | F41: =KANWIL!F41+SURABAYA!F41+KEDIRI!F41+MALANG!F41+MADIUN!F41+BANYUWANGI!F41 -> 159944196 | G41: =KANWIL!G41+SURABAYA!G41+KEDIRI!G41+MALANG!G41+MADIUN!G41+BANYUWANGI!G41 -> 0 | H41: =KANWIL!H41+SURABAYA!H41+KEDIRI!H41+MALANG!H41+MADIUN!H41+BANYUWANGI!H41 -> 3279733 | I41: =KANWIL!I41+SURABAYA!I41+KEDIRI!I41+MALANG!I41+MADIUN!I41+BANYUWANGI!I41 -> 4221101 | J41: =KANWIL!J41+SURABAYA!J41+KEDIRI!J41+MALANG!J41+MADIUN!J41+BANYUWANGI!J41 -> 18572892 | K41: =SUM(F41:J41) -> 186017922 | L41: =KANWIL!L41+SURABAYA!L41+KEDIRI!L41+MALANG!L41+MADIUN!L41+BANYUWANGI!L41 -> 0 | M41: =KANWIL!M41+SURABAYA!M41+KEDIRI!M41+MALANG!M41+MADIUN!M41+BANYUWANGI!M41 -> 0 | N41: =KANWIL!N41+SURABAYA!N41+KEDIRI!N41+MALANG!N41+MADIUN!N41+BANYUWANGI!N41 -> 0 | O41: =SUM(L41:N41) -> 0 | P41: =O41/K41 -> 0
A42: 109 | E42: Beban tunjangan hari raya karyawan | F42: =KANWIL!F42+SURABAYA!F42+KEDIRI!F42+MALANG!F42+MADIUN!F42+BANYUWANGI!F42 -> 2027967651 | G42: =KANWIL!G42+SURABAYA!G42+KEDIRI!G42+MALANG!G42+MADIUN!G42+BANYUWANGI!G42 -> 0 | H42: =KANWIL!H42+SURABAYA!H42+KEDIRI!H42+MALANG!H42+MADIUN!H42+BANYUWANGI!H42 -> 41584457 | I42: =KANWIL!I42+SURABAYA!I42+KEDIRI!I42+MALANG!I42+MADIUN!I42+BANYUWANGI!I42 -> 53520289 | J42: =KANWIL!J42+SURABAYA!J42+KEDIRI!J42+MALANG!J42+MADIUN!J42+BANYUWANGI!J42 -> 235489774 | K42: =SUM(F42:J42) -> 2358562171 | L42: =KANWIL!L42+SURABAYA!L42+KEDIRI!L42+MALANG!L42+MADIUN!L42+BANYUWANGI!L42 -> 1.5073691e+09 | M42: =KANWIL!M42+SURABAYA!M42+KEDIRI!M42+MALANG!M42+MADIUN!M42+BANYUWANGI!M42 -> 0 | N42: =KANWIL!N42+SURABAYA!N42+KEDIRI!N42+MALANG!N42+MADIUN!N42+BANYUWANGI!N42 -> 6.8942821e+08 | O42: =SUM(L42:N42) -> 2.1967973e+09 | P42: =O42/K42 -> 0.93141376
A43: 110 | E43: Beban tunjangan PPh 21 karyawan | F43: =KANWIL!F43+SURABAYA!F43+KEDIRI!F43+MALANG!F43+MADIUN!F43+BANYUWANGI!F43 -> 6863069834 | G43: =KANWIL!G43+SURABAYA!G43+KEDIRI!G43+MALANG!G43+MADIUN!G43+BANYUWANGI!G43 -> 0 | H43: =KANWIL!H43+SURABAYA!H43+KEDIRI!H43+MALANG!H43+MADIUN!H43+BANYUWANGI!H43 -> 140730562 | I43: =KANWIL!I43+SURABAYA!I43+KEDIRI!I43+MALANG!I43+MADIUN!I43+BANYUWANGI!I43 -> 181123936 | J43: =KANWIL!J43+SURABAYA!J43+KEDIRI!J43+MALANG!J43+MADIUN!J43+BANYUWANGI!J43 -> 796947017 | K43: =SUM(F43:J43) -> 7981871349 | L43: =KANWIL!L43+SURABAYA!L43+KEDIRI!L43+MALANG!L43+MADIUN!L43+BANYUWANGI!L43 -> 9.8119677e+08 | M43: =KANWIL!M43+SURABAYA!M43+KEDIRI!M43+MALANG!M43+MADIUN!M43+BANYUWANGI!M43 -> 0 | N43: =KANWIL!N43+SURABAYA!N43+KEDIRI!N43+MALANG!N43+MADIUN!N43+BANYUWANGI!N43 -> 4.7106768e+08 | O43: =SUM(L43:N43) -> 1.4522645e+09 | P43: =O43/K43 -> 0.18194536
A44: 111 | E44: Beban tunjangan transportasi karyawan | F44: =KANWIL!F44+SURABAYA!F44+KEDIRI!F44+MALANG!F44+MADIUN!F44+BANYUWANGI!F44 -> 313456462 | G44: =KANWIL!G44+SURABAYA!G44+KEDIRI!G44+MALANG!G44+MADIUN!G44+BANYUWANGI!G44 -> 0 | H44: =KANWIL!H44+SURABAYA!H44+KEDIRI!H44+MALANG!H44+MADIUN!H44+BANYUWANGI!H44 -> 6427576 | I44: =KANWIL!I44+SURABAYA!I44+KEDIRI!I44+MALANG!I44+MADIUN!I44+BANYUWANGI!I44 -> 8272461 | J44: =KANWIL!J44+SURABAYA!J44+KEDIRI!J44+MALANG!J44+MADIUN!J44+BANYUWANGI!J44 -> 36398899 | K44: =SUM(F44:J44) -> 364555398 | L44: =KANWIL!L44+SURABAYA!L44+KEDIRI!L44+MALANG!L44+MADIUN!L44+BANYUWANGI!L44 -> 1.784013e+08 | M44: =KANWIL!M44+SURABAYA!M44+KEDIRI!M44+MALANG!M44+MADIUN!M44+BANYUWANGI!M44 -> 0 | N44: =KANWIL!N44+SURABAYA!N44+KEDIRI!N44+MALANG!N44+MADIUN!N44+BANYUWANGI!N44 -> 78315368 | O44: =SUM(L44:N44) -> 2.5671667e+08 | P44: =O44/K44 -> 0.7041911
A45: 112 | E45: Beban tunjangan jabatan | F45: =KANWIL!F45+SURABAYA!F45+KEDIRI!F45+MALANG!F45+MADIUN!F45+BANYUWANGI!F45 -> 4718703168 | G45: =KANWIL!G45+SURABAYA!G45+KEDIRI!G45+MALANG!G45+MADIUN!G45+BANYUWANGI!G45 -> 0 | H45: =KANWIL!H45+SURABAYA!H45+KEDIRI!H45+MALANG!H45+MADIUN!H45+BANYUWANGI!H45 -> 96759287 | I45: =KANWIL!I45+SURABAYA!I45+KEDIRI!I45+MALANG!I45+MADIUN!I45+BANYUWANGI!I45 -> 124531748 | J45: =KANWIL!J45+SURABAYA!J45+KEDIRI!J45+MALANG!J45+MADIUN!J45+BANYUWANGI!J45 -> 547940862 | K45: =SUM(F45:J45) -> 5487935065 | L45: =KANWIL!L45+SURABAYA!L45+KEDIRI!L45+MALANG!L45+MADIUN!L45+BANYUWANGI!L45 -> 2.3255393e+09 | M45: =KANWIL!M45+SURABAYA!M45+KEDIRI!M45+MALANG!M45+MADIUN!M45+BANYUWANGI!M45 -> 0 | N45: =KANWIL!N45+SURABAYA!N45+KEDIRI!N45+MALANG!N45+MADIUN!N45+BANYUWANGI!N45 -> 1.021819e+09 | O45: =SUM(L45:N45) -> 3347358334 | P45: =O45/K45 -> 0.6099486
A46: 113 | E46: Beban tunjangan cuti besar | F46: =KANWIL!F46+SURABAYA!F46+KEDIRI!F46+MALANG!F46+MADIUN!F46+BANYUWANGI!F46 -> 109801507 | G46: =KANWIL!G46+SURABAYA!G46+KEDIRI!G46+MALANG!G46+MADIUN!G46+BANYUWANGI!G46 -> 0 | H46: =KANWIL!H46+SURABAYA!H46+KEDIRI!H46+MALANG!H46+MADIUN!H46+BANYUWANGI!H46 -> 2251533 | I46: =KANWIL!I46+SURABAYA!I46+KEDIRI!I46+MALANG!I46+MADIUN!I46+BANYUWANGI!I46 -> 2897782 | J46: =KANWIL!J46+SURABAYA!J46+KEDIRI!J46+MALANG!J46+MADIUN!J46+BANYUWANGI!J46 -> 12750269 | K46: =SUM(F46:J46) -> 127701091 | L46: =KANWIL!L46+SURABAYA!L46+KEDIRI!L46+MALANG!L46+MADIUN!L46+BANYUWANGI!L46 -> 0 | M46: =KANWIL!M46+SURABAYA!M46+KEDIRI!M46+MALANG!M46+MADIUN!M46+BANYUWANGI!M46 -> 0 | N46: =KANWIL!N46+SURABAYA!N46+KEDIRI!N46+MALANG!N46+MADIUN!N46+BANYUWANGI!N46 -> 0 | O46: =SUM(L46:N46) -> 0 | P46: =O46/K46 -> 0
A47: 114 | E47: Beban tunjangan cuti tahunan | F47: =KANWIL!F47+SURABAYA!F47+KEDIRI!F47+MALANG!F47+MADIUN!F47+BANYUWANGI!F47 -> 1053484460 | G47: =KANWIL!G47+SURABAYA!G47+KEDIRI!G47+MALANG!G47+MADIUN!G47+BANYUWANGI!G47 -> 0 | H47: =KANWIL!H47+SURABAYA!H47+KEDIRI!H47+MALANG!H47+MADIUN!H47+BANYUWANGI!H47 -> 21602207 | I47: =KANWIL!I47+SURABAYA!I47+KEDIRI!I47+MALANG!I47+MADIUN!I47+BANYUWANGI!I47 -> 27802609 | J47: =KANWIL!J47+SURABAYA!J47+KEDIRI!J47+MALANG!J47+MADIUN!J47+BANYUWANGI!J47 -> 122331745 | K47: =SUM(F47:J47) -> 1225221021 | L47: =KANWIL!L47+SURABAYA!L47+KEDIRI!L47+MALANG!L47+MADIUN!L47+BANYUWANGI!L47 -> 0 | M47: =KANWIL!M47+SURABAYA!M47+KEDIRI!M47+MALANG!M47+MADIUN!M47+BANYUWANGI!M47 -> 0 | N47: =KANWIL!N47+SURABAYA!N47+KEDIRI!N47+MALANG!N47+MADIUN!N47+BANYUWANGI!N47 -> 0 | O47: =SUM(L47:N47) -> 0 | P47: =O47/K47 -> 0
...

Sheet KANWIL
D1: PT JAMKRINDO KANWIL SURABAYA
D2: LABA RUGI RKA TAHUN 2026
O4: =#REF! -> #REF!
D5: URAIAN | F5: KANWIL SURABAYA | L5: REALISASI KANWIL SURABAYA | P5: %
F6: KUR | G6: PEN | H6: KBG/SURETYSHIP | I6: KONSUMTIF | J6: PRODUKTIF | K6: TOTAL | L6: KUR | M6: PEN | N6: NON KUR | O6: TOTAL | P6: %
C8: X1 | D8: VOLUME | O8: =SUM(L8:N8) -> 0 | P8: 0
C10: X2 | D10: PENDAPATAN PENJAMINAN
A11: 7 | B11: 8 | E11: Imbal Jasa Penjaminan Bruto | O11: =SUM(L11:N11) -> 0 | P11: 0
A12: 12 | B12: 10 | E12: Restitusi penjaminan kredit | O12: =SUM(L12:N12) -> 0 | P12: 0
A13: 9 | B13: 9 | E13: Premi Penjaminan Ulang | O13: =SUM(L13:N13) -> 0 | P13: 0
C14: Y2 | E14: IMBAL JASA PENJAMINAN BERSIH | O14: =O11-O12-O13 -> 0 | P14: 0
C16: X2 | D16: BEBAN KLAIM
A17: 22 | B17: 13 | E17: Beban Klaim | O17: =SUM(L17:N17) -> 0 | P17: 0
A18: 24 | B18: 14 | E18: Kenaikan (Penurunan) Cadangan Klaim | O18: =SUM(L18:N18) -> 0 | P18: 0
A19: 32 | B19: 15 | E19: Pendapatan Subrogasi | O19: =SUM(L19:N19) -> 0 | P19: 0
A20: 37 | B20: 16 | E20: Beban Komisi Netto | O20: =SUM(L20:N20) -> 0 | P20: 0
C21: Y2 | E21: JUMLAH BEBAN KLAIM | O21: =O17+O18-O19-O20 -> 0 | P21: 0
C23: X1 | D23: PENJAMINAN BERSIH | O23: =O14-O21 -> 0 | P23: 0
B25: 19 | C25: X1 | D25: PENDAPATAN INVESTASI BERSIH | O25: 0 | P25: 0
C27: X1 | D27: BEBAN USAHA
C28: X2 | E28: BEBAN KARYAWAN
A29: 94 | E29: Beban gaji karyawan | F29: 1696793732 | G29: 0 | H29: 34793575 | I29: 44780247 | J29: 197033505 | K29: =SUM(F29:J29) -> 1973401059 | L29: 7.7489527e+08 | N29: 3.4037017e+08 | O29: =SUM(L29:N29) -> 1.1152654e+09 | P29: =O29/K29 -> 0.5651489
A30: 95 | E30: Beban lembur karyawan | F30: 43007556 | G30: 0 | H30: 881891 | I30: 1135017 | J30: 4994083 | K30: =SUM(F30:J30) -> 50018547 | L30: 16581527 | N30: 6183014.3 | O30: =SUM(L30:N30) -> 22764541 | P30: =O30/K30 -> 0.455122
A31: 96 | E31: Beban asuransi kesehatan karyawan | F31: 180463354 | G31: 0 | H31: 3700488 | I31: 4762626 | J31: 20955598 | K31: =SUM(F31:J31) -> 209882066 | L31: 6418318.8 | N31: 2790681.2 | O31: =SUM(L31:N31) -> 9209000 | P31: =O31/K31 -> 0.043877022
A32: 97 | E32: Beban asuransi jiwa karyawan | F32: 8268054 | G32: 0 | H32: 169540 | I32: 218203 | J32: 960095 | K32: =SUM(F32:J32) -> 9615892 | L32: 0 | N32: 0 | O32: =SUM(L32:N32) -> 0 | P32: =O32/K32 -> 0
A33: 100 | E33: Beban dana pensiun | F33: 131045331 | G33: 0 | H33: 2687148 | I33: 3458430 | J33: 15217124 | K33: =SUM(F33:J33) -> 152408033 | L33: 0 | N33: 0 | O33: =SUM(L33:N33) -> 0 | P33: =O33/K33 -> 0
A34: 101 | E34: Beban kompensasi kinerja karyawan | F34: 2154273121 | G34: 0 | H34: 44174411 | I34: 56853630 | J34: 250156501 | K34: =SUM(F34:J34) -> 2505457663 | L34: 9.9943875e+08 | N34: 4.3888718e+08 | O34: =SUM(L34:N34) -> 1.4383259e+09 | P34: =O34/K34 -> 0.57407712
A35: 102 | E35: Biaya jasa kini karyawan | F35: 0 | G35: 0 | H35: 0 | I35: 0 | J35: 0 | K35: =SUM(F35:J35) -> 0 | L35: 0 | N35: 0 | O35: =SUM(L35:N35) -> 0 | P35: 0
A36: 103 | E36: Biaya jasa lalu karyawan | F36: 0 | G36: 0 | H36: 0 | I36: 0 | J36: 0 | K36: =SUM(F36:J36) -> 0 | L36: 0 | N36: 0 | O36: =SUM(L36:N36) -> 0 | P36: 0
A37: 104 | E37: Bunga atas imbalan pasca kerja karyawan | F37: 198153866 | G37: 0 | H37: 4063241 | I37: 5229498 | J37: 23009839 | K37: =SUM(F37:J37) -> 230456444 | L37: 0 | N37: 0 | O37: =SUM(L37:N37) -> 0 | P37: =O37/K37 -> 0
A38: 105 | E38: Beban BPJS kesehatan karyawan | F38: 50291539 | G38: 0 | H38: 1031252 | I38: 1327249 | J38: 5839908 | K38: =SUM(F38:J38) -> 58489948 | L38: 0 | N38: 0 | O38: =SUM(L38:N38) -> 0 | P38: =O38/K38 -> 0
A39: 106 | E39: Beban BPJS jaminan hari tua karyawan | F39: 71343529 | G39: 0 | H39: 1462934 | I39: 1882834 | J39: 8284487 | K39: =SUM(F39:J39) -> 82973784 | L39: 0 | N39: 0 | O39: =SUM(L39:N39) -> 0 | P39: =O39/K39 -> 0
A40: 107 | E40: Beban BPJS jaminan kecelakaan kerja dan jaminan kematian karyawan | F40: 10354282 | G40: 0 | H40: 212320 | I40: 273261 | J40: 1202350 | K40: =SUM(F40:J40) -> 12042213 | L40: 0 | N40: 0 | O40: =SUM(L40:N40) -> 0 | P40: =O40/K40 -> 0
A41: 108 | E41: Beban BPJS jaminan pensiun karyawan | F41: 23991631 | G41: 0 | H41: 491960 | I41: 633165 | J41: 2785934 | K41: =SUM(F41:J41) -> 27902690 | L41: 0 | N41: 0 | O41: =SUM(L41:N41) -> 0 | P41: =O41/K41 -> 0
A42: 109 | E42: Beban tunjangan hari raya karyawan | F42: 401073878 | G42: 0 | H42: 8224214 | I42: 10584779 | J42: 46573128 | K42: =SUM(F42:J42) -> 466455999 | L42: 3.018787e+08 | N42: 1.3807083e+08 | O42: =SUM(L42:N42) -> 4.3994953e+08 | P42: =O42/K42 -> 0.94317477
A43: 110 | E43: Beban tunjangan PPh 21 karyawan | F43: 976585 | G43: 0 | H43: 20025 | I43: 25773 | J43: 113402 | K43: =SUM(F43:J43) -> 1135785 | L43: 0 | N43: 0 | O43: =SUM(L43:N43) -> 0 | P43: =O43/K43 -> 0
A44: 111 | E44: Beban tunjangan transportasi karyawan | F44: 102363826 | G44: 0 | H44: 2099020 | I44: 2701494 | J44: 11886597 | K44: =SUM(F44:J44) -> 119050937 | L44: 33038265 | N44: 14511735 | O44: =SUM(L44:N44) -> 47550000 | P44: =O44/K44 -> 0.39940887
A45: 112 | E45: Beban tunjangan jabatan | F45: 990927668 | G45: 0 | H45: 20319450 | I45: 26151667 | J45: 115067581 | K45: =SUM(F45:J45) -> 1152466366 | L45: 4.9016795e+08 | N45: 2.1536538e+08 | O45: =SUM(L45:N45) -> 705533333 | P45: =O45/K45 -> 0.61219429
A46: 113 | E46: Beban tunjangan cuti besar | F46: 16470226 | G46: 0 | H46: 337730 | I46: 434667 | J46: 1912540 | K46: =SUM(F46:J46) -> 19155163 | L46: 0 | N46: 0 | O46: =SUM(L46:N46) -> 0 | P46: =O46/K46 -> 0
A47: 114 | E47: Beban tunjangan cuti tahunan | F47: 158022668 | G47: 0 | H47: 3240331 | I47: 4170391 | J47: 18349762 | K47: =SUM(F47:J47) -> 183783152 | L47: 0 | N47: 0 | O47: =SUM(L47:N47) -> 0 | P47: =O47/K47 -> 0
...

Sheet SURABAYA
D1: PT JAMKRINDO KANWIL SURABAYA
D2: LABA RUGI RKA TAHUN 2026
O4: =#REF! -> #REF!
D5: URAIAN | F5: KANCA SURABAYA | L5: REALISASI KANCA SURABAYA | P5: %
F6: KUR | G6: PEN | H6: KBG/SURETYSHIP | I6: KONSUMTIF | J6: PRODUKTIF | K6: TOTAL | L6: KUR | M6: PEN | N6: NON KUR | O6: TOTAL | P6: %
C8: X1 | D8: VOLUME | F8: 9912949637720 | G8: 0 | H8: 3913532224491 | I8: 974545539188 | J8: 2361265957530 | K8: =SUM(F8:J8) -> 17162293358929 | L8: 7.4752426e+12 | N8: 2.2586704e+12 | O8: =SUM(L8:N8) -> 9.7339129e+12 | P8: =O8/K8 -> 0.56716854
C10: X2 | D10: PENDAPATAN PENJAMINAN
A11: 7 | B11: 8 | E11: Imbal Jasa Penjaminan Bruto | F11: 358429774172 | G11: 0 | H11: 12754022487 | I11: 9459354711 | J11: 42658164985 | K11: =SUM(F11:J11) -> 423301316355 | L11: 1.9051406e+11 | M11: 0 | N11: 7.4534465e+10 | O11: =SUM(L11:N11) -> 2.6504852e+11 | P11: =O11/K11 -> 0.62614623
A12: 12 | B12: 10 | E12: Restitusi penjaminan kredit | F12: 0 | G12: 0 | H12: 0 | I12: 0 | J12: 0 | K12: =SUM(F12:J12) -> 0 | L12: 0 | M12: 0 | N12: 0 | O12: =SUM(L12:N12) -> 0 | P12: 0
A13: 9 | B13: 9 | E13: Premi Penjaminan Ulang | F13: 32275195681 | G13: 0 | H13: 1548572196 | I13: 1411596254 | J13: 24666604293 | K13: =SUM(F13:J13) -> 59901968424 | L13: 2.055736e+10 | M13: 0 | N13: 9.8556143e+09 | O13: =SUM(L13:N13) -> 3.0412974e+10 | P13: =O13/K13 -> 0.50771244
C14: Y2 | E14: IMBAL JASA PENJAMINAN BERSIH | F14: =F11-F12-F13 -> 326154578491 | G14: =G11-G12-G13 -> 0 | H14: =H11-H12-H13 -> 11205450291 | I14: =I11-I12-I13 -> 8047758457 | J14: =J11-J12-J13 -> 17991560692 | K14: =K11-K12-K13 -> 363399347931 | L14: =L11-L12-L13 -> 1.699567e+11 | M14: =M11-M12-M13 -> 0 | ... O14: =O11-O12-O13 -> 2.3463555e+11 | P14: =O14/K14 -> 0.6456686
C16: X2 | D16: BEBAN KLAIM
A17: 22 | B17: 13 | E17: Beban Klaim | F17: 279117753977 | G17: 22334975222 | H17: 5202817631 | I17: 5124694714 | J17: 37261618379 | K17: =SUM(F17:J17) -> 349041859923 | L17: 1.3797285e+11 | M17: 4359222990 | N17: 6.3153505e+10 | O17: =SUM(L17:N17) -> 2.0548558e+11 | P17: =O17/K17 -> 0.58871328
A18: 24 | B18: 14 | E18: Kenaikan (Penurunan) Cadangan Klaim | F18: 1747285621 | G18: -5867662416 | H18: 17700890 | I18: 264667074 | J18: 8523487423 | K18: =SUM(F18:J18) -> 4685478592 | L18: 1.4579893e+10 | M18: -5.8676624e+09 | N18: 2.1161492e+09 | O18: =SUM(L18:N18) -> 1.082838e+10 | P18: =O18/K18 -> 2.3110509
A19: 32 | B19: 15 | E19: Pendapatan Subrogasi | F19: 71739819407 | G19: 17075082318 | H19: 59056287 | I19: 120506747 | J19: 26509953142 | K19: =SUM(F19:J19) -> 115504417901 | L19: 5.3678578e+10 | M19: 7.6528895e+09 | N19: 1.7958707e+10 | O19: =SUM(L19:N19) -> 7.9290175e+10 | P19: =O19/K19 -> 0.68646876
A20: 37 | B20: 16 | E20: Beban Komisi Netto | F20: 5093038920 | G20: 0 | H20: 269126234 | I20: 215756309 | J20: 3766766262 | K20: =SUM(F20:J20) -> 9344687725 | L20: 3.3672537e+09 | M20: 0 | N20: 1.2715834e+09 | O20: =SUM(L20:N20) -> 4.6388371e+09 | P20: =O20/K20 -> 0.49641435
C21: Y2 | E21: JUMLAH BEBAN KLAIM | F21: =F17+F18-F19-F20 -> 204032181271 | G21: =G17+G18-G19-G20 -> -607769512 | H21: =H17+H18-H19-H20 -> 4892336000 | I21: =I17+I18-I19-I20 -> 5053098732 | J21: =J17+J18-J19-J20 -> 15508386398 | K21: =K17+K18-K19-K20 -> 228878232889 | L21: =L17+L18-L19-L20 -> 9.5506912e+10 | M21: =M17+M18-M19-M20 -> -9.1613289e+09 | ... O21: =O17+O18-O19-O20 -> 1.3238495e+11 | P21: =O21/K21 -> 0.57840776
C23: X1 | D23: PENJAMINAN BERSIH | F23: =F14-F21 -> 122122397220 | G23: =G14-G21 -> 607769512 | H23: =H14-H21 -> 6313114291 | I23: =I14-I21 -> 2994659725 | J23: =J14-J21 -> 2483174294 | K23: =K14-K21 -> 134521115042 | L23: =L14-L21 -> 7.4449787e+10 | M23: =M14-M21 -> 9.1613289e+09 | ... O23: =O14-O21 -> 1.022506e+11 | P23: =O23/K23 -> 0.7601082
B25: 19 | C25: X1 | D25: PENDAPATAN INVESTASI BERSIH | F25: 0 | G25: 0 | H25: 0 | I25: 0 | J25: 0 | K25: 0 | O25: 0 | P25: 0
C27: X1 | D27: BEBAN USAHA
C28: X2 | E28: BEBAN KARYAWAN
A29: 94 | E29: Beban gaji karyawan | F29: 2019992538 | G29: 0 | H29: 41420923 | I29: 53309818 | J29: 234563696 | K29: =SUM(F29:J29) -> 2349286975 | L29: 1.0430392e+09 | N29: 4.5792749e+08 | O29: =SUM(L29:N29) -> 1500966714 | P29: =O29/K29 -> 0.63890309
A30: 95 | E30: Beban lembur karyawan | F30: 80955400 | G30: 0 | H30: 1660030 | I30: 2136502 | J30: 9400628 | K30: =SUM(F30:J30) -> 94152560 | L30: 40590423 | N30: 17569109 | O30: =SUM(L30:N30) -> 58159532 | P30: =O30/K30 -> 0.61771589
A31: 96 | E31: Beban asuransi kesehatan karyawan | F31: 360926704 | G31: 0 | H31: 7400976 | I31: 9525251 | J31: 41911195 | K31: =SUM(F31:J31) -> 419764126 | L31: 0 | N31: 0 | O31: =SUM(L31:N31) -> 0 | P31: =O31/K31 -> 0
A32: 97 | E32: Beban asuransi jiwa karyawan | F32: 16536107 | G32: 0 | H32: 339081 | I32: 436406 | J32: 1920190 | K32: =SUM(F32:J32) -> 19231784 | L32: 0 | N32: 0 | O32: =SUM(L32:N32) -> 0 | P32: =O32/K32 -> 0
A33: 100 | E33: Beban dana pensiun | F33: 262090662 | G33: 0 | H33: 5374296 | I33: 6916860 | J33: 30434248 | K33: =SUM(F33:J33) -> 304816066 | L33: 0 | N33: 0 | O33: =SUM(L33:N33) -> 0 | P33: =O33/K33 -> 0
A34: 101 | E34: Beban kompensasi kinerja karyawan | F34: 2639551770 | G34: 0 | H34: 54125284 | I34: 69660665 | J34: 306507577 | K34: =SUM(F34:J34) -> 3069845296 | L34: 1.4262024e+09 | N34: 6.2629345e+08 | O34: =SUM(L34:N34) -> 2.0524958e+09 | P34: =O34/K34 -> 0.66859911
A35: 102 | E35: Biaya jasa kini karyawan | F35: 0 | G35: 0 | H35: 0 | I35: 0 | J35: 0 | K35: =SUM(F35:J35) -> 0 | L35: 0 | N35: 0 | O35: =SUM(L35:N35) -> 0 | P35: 0
A36: 103 | E36: Biaya jasa lalu karyawan | F36: 0 | G36: 0 | H36: 0 | I36: 0 | J36: 0 | K36: =SUM(F36:J36) -> 0 | L36: 0 | N36: 0 | O36: =SUM(L36:N36) -> 0 | P36: 0
A37: 104 | E37: Bunga atas imbalan pasca kerja karyawan | F37: 396307733 | G37: 0 | H37: 8126482 | I37: 10458996 | J37: 46019678 | K37: =SUM(F37:J37) -> 460912889 | L37: 0 | N37: 0 | O37: =SUM(L37:N37) -> 0 | P37: =O37/K37 -> 0
A38: 105 | E38: Beban BPJS kesehatan karyawan | F38: 100583081 | G38: 0 | H38: 2062505 | I38: 2654498 | J38: 11679815 | K38: =SUM(F38:J38) -> 116979899 | L38: 0 | N38: 0 | O38: =SUM(L38:N38) -> 0 | P38: =O38/K38 -> 0
A39: 106 | E39: Beban BPJS jaminan hari tua karyawan | F39: 142687058 | G39: 0 | H39: 2925867 | I39: 3765668 | J39: 16568974 | K39: =SUM(F39:J39) -> 165947567 | L39: 0 | N39: 0 | O39: =SUM(L39:N39) -> 0 | P39: =O39/K39 -> 0
A40: 107 | E40: Beban BPJS jaminan kecelakaan kerja dan jaminan kematian karyawan | F40: 20708564 | G40: 0 | H40: 424639 | I40: 546522 | J40: 2404701 | K40: =SUM(F40:J40) -> 24084426 | L40: 0 | N40: 0 | O40: =SUM(L40:N40) -> 0 | P40: =O40/K40 -> 0
A41: 108 | E41: Beban BPJS jaminan pensiun karyawan | F41: 47983259 | G41: 0 | H41: 983920 | I41: 1266331 | J41: 5571867 | K41: =SUM(F41:J41) -> 55805377 | L41: 0 | N41: 0 | O41: =SUM(L41:N41) -> 0 | P41: =O41/K41 -> 0
A42: 109 | E42: Beban tunjangan hari raya karyawan | F42: 695650945 | G42: 0 | H42: 14264659 | I42: 18358991 | J42: 80779732 | K42: =SUM(F42:J42) -> 809054327 | L42: 4.307819e+08 | N42: 1.9702752e+08 | O42: =SUM(L42:N42) -> 6.2780943e+08 | P42: =O42/K42 -> 0.77597932
A43: 110 | E43: Beban tunjangan PPh 21 karyawan | F43: 1603647260 | G43: 0 | H43: 32883562 | I43: 42322009 | J43: 186217237 | K43: =SUM(F43:J43) -> 1865070068 | L43: 2.489024e+08 | N43: 1.1815618e+08 | O43: =SUM(L43:N43) -> 3.6705858e+08 | P43: =O43/K43 -> 0.19680686
A44: 111 | E44: Beban tunjangan transportasi karyawan | F44: 83963494 | G44: 0 | H44: 1721712 | I44: 2215889 | J44: 9749931 | K44: =SUM(F44:J44) -> 97651026 | L44: 38538807 | N44: 16927860 | O44: =SUM(L44:N44) -> 55466667 | P44: =O44/K44 -> 0.56800906
A45: 112 | E45: Beban tunjangan jabatan | F45: 943740633 | G45: 0 | H45: 19351858 | I45: 24906350 | J45: 109588173 | K45: =SUM(F45:J45) -> 1097587014 | L45: 5.9729626e+08 | N45: 2.6251207e+08 | O45: =SUM(L45:N45) -> 859808334 | P45: =O45/K45 -> 0.78336234
A46: 113 | E46: Beban tunjangan cuti besar | F46: 32940452 | G46: 0 | H46: 675460 | I46: 869335 | J46: 3825081 | K46: =SUM(F46:J46) -> 38310328 | L46: 0 | N46: 0 | O46: =SUM(L46:N46) -> 0 | P46: =O46/K46 -> 0
A47: 114 | E47: Beban tunjangan cuti tahunan | F47: 316045338 | G47: 0 | H47: 6480662 | I47: 8340783 | J47: 36699523 | K47: =SUM(F47:J47) -> 367566306 | L47: 0 | N47: 0 | O47: =SUM(L47:N47) -> 0 | P47: =O47/K47 -> 0
...

Sheet KEDIRI
D1: PT JAMKRINDO KANWIL SURABAYA
D2: LABA RUGI RKA TAHUN 2026
O4: =#REF! -> #REF!
D5: URAIAN | F5: KANCA KEDIRI | L5: REALISASI KANCA KEDIRI | P5: %
F6: KUR | G6: PEN | H6: KBG/SURETYSHIP | I6: KONSUMTIF | J6: PRODUKTIF | K6: TOTAL | L6: KUR | M6: PEN | N6: NON KUR | O6: TOTAL | P6: %
C8: X1 | D8: VOLUME | F8: 5539589503431 | G8: 0 | H8: 729641601176 | I8: 544598977781 | J8: 1004253035090 | K8: =SUM(F8:J8) -> 7818083117478 | L8: 4.232705e+12 | N8: 9.0602604e+11 | O8: =SUM(L8:N8) -> 5.1387311e+12 | P8: =O8/K8 -> 0.65728785
C10: X2 | D10: PENDAPATAN PENJAMINAN
A11: 7 | B11: 8 | E11: Imbal Jasa Penjaminan Bruto | F11: 200298991450 | G11: 0 | H11: 2377868599 | I11: 5286109986 | J11: 22927120245 | K11: =SUM(F11:J11) -> 230890090280 | L11: 1.0346593e+11 | M11: 0 | N11: 4.1542495e+10 | O11: =SUM(L11:N11) -> 1.4500842e+11 | P11: =O11/K11 -> 0.62804091
A12: 12 | B12: 10 | E12: Restitusi penjaminan kredit | F12: 0 | G12: 0 | H12: 0 | I12: 0 | J12: 0 | K12: =SUM(F12:J12) -> 0 | L12: 0 | M12: 0 | N12: 0 | O12: =SUM(L12:N12) -> 0 | P12: =O12/K12 -> #DIV/0!
A13: 9 | B13: 9 | E13: Premi Penjaminan Ulang | F13: 18036138761 | G13: 0 | H13: 288716850 | I13: 788833201 | J13: 13671394317 | K13: =SUM(F13:J13) -> 32785083129 | L13: 1.0807965e+10 | M13: 0 | N13: 5.3056972e+09 | O13: =SUM(L13:N13) -> 16113662010 | P13: =O13/K13 -> 0.49149371
C14: Y2 | E14: IMBAL JASA PENJAMINAN BERSIH | F14: =F11-F12-F13 -> 182262852689 | G14: =G11-G12-G13 -> 0 | H14: =H11-H12-H13 -> 2089151749 | I14: =I11-I12-I13 -> 4497276785 | J14: =J11-J12-J13 -> 9255725928 | K14: =K11-K12-K13 -> 198105007151 | L14: =L11-L12-L13 -> 9.2657962e+10 | M14: =M11-M12-M13 -> 0 | ... O14: =O11-O12-O13 -> 1.2889476e+11 | P14: =O14/K14 -> 0.65063858
C16: X2 | D16: BEBAN KLAIM
A17: 22 | B17: 13 | E17: Beban Klaim | F17: 149669107251 | G17: 1889067548 | H17: 158460622 | I17: 500000000 | J17: 25924281317 | K17: =SUM(F17:J17) -> 178140916738 | L17: 5.7450231e+10 | M17: 116546366 | N17: 2.5399709e+10 | O17: =SUM(L17:N17) -> 8.2966487e+10 | P17: =O17/K17 -> 0.46573515
A18: 24 | B18: 14 | E18: Kenaikan (Penurunan) Cadangan Klaim | F18: 1219679297 | G18: -151546366 | H18: 17700891 | I18: 0 | J18: 3523812717 | K18: =SUM(F18:J18) -> 4609646539 | L18: 8.0102758e+09 | M18: -1.5154637e+08 | N18: 9.2901233e+09 | O18: =SUM(L18:N18) -> 1.7148853e+10 | P18: =O18/K18 -> 3.7202099
A19: 32 | B19: 15 | E19: Pendapatan Subrogasi | F19: 43057773776 | G19: 4180457975 | H19: 30365867 | I19: 61962783 | J19: 19772876680 | K19: =SUM(F19:J19) -> 67103437081 | L19: 1.4900423e+10 | M19: 9.184166e+08 | N19: 8.3941876e+09 | O19: =SUM(L19:N19) -> 2.4213027e+10 | P19: =O19/K19 -> 0.3608314
A20: 37 | B20: 16 | E20: Beban Komisi Netto | F20: 2846109985 | G20: 0 | H20: 50176077 | I20: 120569702 | J20: 2085992135 | K20: =SUM(F20:J20) -> 5102847899 | L20: 1.7865182e+09 | M20: 0 | N20: 7.6299796e+08 | O20: =SUM(L20:N20) -> 2.5495161e+09 | P20: =O20/K20 -> 0.49962612
C21: Y2 | E21: JUMLAH BEBAN KLAIM | F21: =F17+F18-F19-F20 -> 104984902787 | G21: =G17+G18-G19-G20 -> -2442936793 | H21: =H17+H18-H19-H20 -> 95619569 | I21: =I17+I18-I19-I20 -> 317467515 | J21: =J17+J18-J19-J20 -> 7589225219 | K21: =K17+K18-K19-K20 -> 110544278297 | L21: =L17+L18-L19-L20 -> 4.8773566e+10 | M21: =M17+M18-M19-M20 -> -953416597 | ... O21: =O17+O18-O19-O20 -> 7.3352796e+10 | P21: =O21/K21 -> 0.66356031
C23: X1 | D23: PENJAMINAN BERSIH | F23: =F14-F21 -> 77277949902 | G23: =G14-G21 -> 2442936793 | H23: =H14-H21 -> 1993532180 | I23: =I14-I21 -> 4179809270 | J23: =J14-J21 -> 1666500709 | K23: =K14-K21 -> 87560728854 | L23: =L14-L21 -> 4.3884396e+10 | M23: =M14-M21 -> 953416597 | ... O23: =O14-O21 -> 5.5541963e+10 | P23: =O23/K23 -> 0.63432505
B25: 19 | C25: X1 | D25: PENDAPATAN INVESTASI BERSIH | F25: 0 | G25: 0 | H25: 0 | I25: 0 | J25: 0 | K25: 0 | O25: 0 | P25: 0
C27: X1 | D27: BEBAN USAHA
C28: X2 | E28: BEBAN KARYAWAN
A29: 94 | E29: Beban gaji karyawan | F29: 969596418 | G29: 0 | H29: 19882043 | I29: 25588713 | J29: 112590574 | K29: =SUM(F29:J29) -> 1127657748 | L29: 5.1681078e+08 | N29: 2.2694104e+08 | O29: =SUM(L29:N29) -> 743751821 | P29: =O29/K29 -> 0.65955457
A30: 95 | E30: Beban lembur karyawan | F30: 35417988 | G30: 0 | H30: 726263 | I30: 934720 | J30: 4112775 | K30: =SUM(F30:J30) -> 41191746 | L30: 13555184 | N30: 6085485.9 | O30: =SUM(L30:N30) -> 19640670 | P30: =O30/K30 -> 0.47681082
A31: 96 | E31: Beban asuransi kesehatan karyawan | F31: 180463352 | G31: 0 | H31: 3700488 | I31: 4762626 | J31: 20955598 | K31: =SUM(F31:J31) -> 209882064 | L31: 7643750 | N31: 2856250 | O31: =SUM(L31:N31) -> 10500000 | P31: =O31/K31 -> 0.050028096
A32: 97 | E32: Beban asuransi jiwa karyawan | F32: 8268054 | G32: 0 | H32: 169540 | I32: 218203 | J32: 960095 | K32: =SUM(F32:J32) -> 9615892 | L32: 0 | N32: 0 | O32: =SUM(L32:N32) -> 0 | P32: =O32/K32 -> 0
A33: 100 | E33: Beban dana pensiun | F33: 131045331 | G33: 0 | H33: 2687148 | I33: 3458430 | J33: 15217124 | K33: =SUM(F33:J33) -> 152408033 | L33: 0 | N33: 0 | O33: =SUM(L33:N33) -> 0 | P33: =O33/K33 -> 0
A34: 101 | E34: Beban kompensasi kinerja karyawan | F34: 1395994313 | G34: 0 | H34: 28625538 | I34: 36841820 | J34: 162104354 | K34: =SUM(F34:J34) -> 1623566025 | L34: 6.7312524e+08 | N34: 2.9559194e+08 | O34: =SUM(L34:N34) -> 9.6871718e+08 | P34: =O34/K34 -> 0.59666017
A35: 102 | E35: Biaya jasa kini karyawan | F35: 0 | G35: 0 | H35: 0 | I35: 0 | J35: 0 | K35: =SUM(F35:J35) -> 0 | L35: 0 | N35: 0 | O35: =SUM(L35:N35) -> 0 | P35: =O35/K35 -> #DIV/0!
A36: 103 | E36: Biaya jasa lalu karyawan | F36: 0 | G36: 0 | H36: 0 | I36: 0 | J36: 0 | K36: =SUM(F36:J36) -> 0 | L36: 0 | N36: 0 | O36: =SUM(L36:N36) -> 0 | P36: =O36/K36 -> #DIV/0!
A37: 104 | E37: Bunga atas imbalan pasca kerja karyawan | F37: 198153866 | G37: 0 | H37: 4063241 | I37: 5229498 | J37: 23009839 | K37: =SUM(F37:J37) -> 230456444 | L37: 0 | N37: 0 | O37: =SUM(L37:N37) -> 0 | P37: =O37/K37 -> 0
A38: 105 | E38: Beban BPJS kesehatan karyawan | F38: 50291541 | G38: 0 | H38: 1031252 | I38: 1327249 | J38: 5839908 | K38: =SUM(F38:J38) -> 58489950 | L38: 0 | N38: 0 | O38: =SUM(L38:N38) -> 0 | P38: =O38/K38 -> 0
A39: 106 | E39: Beban BPJS jaminan hari tua karyawan | F39: 71343529 | G39: 0 | H39: 1462934 | I39: 1882834 | J39: 8284487 | K39: =SUM(F39:J39) -> 82973784 | L39: 0 | N39: 0 | O39: =SUM(L39:N39) -> 0 | P39: =O39/K39 -> 0
A40: 107 | E40: Beban BPJS jaminan kecelakaan kerja dan jaminan kematian karyawan | F40: 10354282 | G40: 0 | H40: 212320 | I40: 273261 | J40: 1202350 | K40: =SUM(F40:J40) -> 12042213 | L40: 0 | N40: 0 | O40: =SUM(L40:N40) -> 0 | P40: =O40/K40 -> 0
... A51: 0 | E51: Beban tunjangan lainnya | F51: 91501256 | G51: 0 | H51: 1876277 | I51: 2414818 | J51: 10625224 | K51: =SUM(F51:J51) -> 106417575 | L51: 58436602 | N51: 25871732 | O51: =SUM(L51:N51) -> 84308334 | P51: =O51/K51 -> 0.7922407
B52: 21 | C52: Y2 | E52: Total Beban Karyawan | F52: =SUM(F29:F51) -> 5710120358 | G52: =SUM(G29:G51) -> 0 | H52: =SUM(H29:H51) -> 117088776 | I52: =SUM(I29:I51) -> 150696336 | J52: =SUM(J29:J51) -> 663065289 | K52: =SUM(K29:K51) -> 6640970759 | L52: =SUM(L29:L51) -> 2.0753305e+09 | M52: =SUM(M29:M51) -> 0 | ... O52: =SUM(O29:O51) -> 2.9916781e+09 | P52: =O52/K52 -> 0.45048807
C54: X2 | E54: BEBAN ADMINISTRASI & UMUM
A55: 169 | E55: Imbal jasa profesional - akuntan publik | F55: 0 | G55: 0 | H55: 0 | I55: 0 | J55: 0 | K55: =SUM(F55:J55) -> 0 | L55: 0 | N55: 0 | O55: =SUM(L55:N55) -> 0 | P55: =O55/K55 -> #DIV/0!
A56: 171 | E56: Imbal jasa profesional - konsultan hukum | F56: 0 | G56: 0 | H56: 0 | I56: 0 | J56: 0 | K56: =SUM(F56:J56) -> 0 | L56: 0 | N56: 0 | O56: =SUM(L56:N56) -> 0 | P56: =O56/K56 -> #DIV/0!
A57: 175 | E57: Imbal jasa profesional - konsultan manajemen (SDM, SOP, Akuntansi dll) | F57: 0 | G57: 0 | H57: 0 | I57: 0 | J57: 0 | K57: =SUM(F57:J57) -> 0 | L57: 0 | N57: 0 | O57: =SUM(L57:N57) -> 0 | P57: =O57/K57 -> #DIV/0!
A58: 176 | E58: Beban imbal jasa profesional IT | F58: 0 | G58: 0 | H58: 0 | I58: 0 | J58: 0 | K58: =SUM(F58:J58) -> 0 | L58: 0 | N58: 0 | O58: =SUM(L58:N58) -> 0 | P58: =O58/K58 -> #DIV/0!
...

Sheet MALANG
D1: PT JAMKRINDO KANWIL SURABAYA
D2: LABA RUGI RKA TAHUN 2026
O4: =#REF! -> #REF!
D5: URAIAN | F5: KANCA MALANG | L5: REALISASI KANCA MALANG | P5: %
F6: KUR | G6: PEN | H6: KBG/SURETYSHIP | I6: KONSUMTIF | J6: PRODUKTIF | K6: TOTAL | L6: KUR | M6: PEN | N6: NON KUR | O6: TOTAL | P6: %
C8: X1 | D8: VOLUME | F8: 4664917476573 | G8: 0 | H8: 795972655829 | I8: 458609665500 | J8: 884960450602 | K8: =SUM(F8:J8) -> 6804460248504 | L8: 3.1262652e+12 | N8: 4.1777788e+11 | O8: =SUM(L8:N8) -> 3.5440431e+12 | P8: =O8/K8 -> 0.52084118
C10: X2 | D10: PENDAPATAN PENJAMINAN
A11: 7 | B11: 8 | E11: Imbal Jasa Penjaminan Bruto | F11: 168672834905 | G11: 0 | H11: 2594038472 | I11: 4451461041 | J11: 19420563629 | K11: =SUM(F11:J11) -> 195138898047 | L11: 8.6405665e+10 | M11: 0 | N11: 2.8404527e+10 | O11: =SUM(L11:N11) -> 1.1481019e+11 | P11: =O11/K11 -> 0.58835113
A12: 12 | B12: 10 | E12: Restitusi penjaminan kredit | F12: 0 | G12: 0 | H12: 0 | I12: 0 | J12: 0 | K12: =SUM(F12:J12) -> 0 | L12: 0 | M12: 0 | N12: 0 | O12: =SUM(L12:N12) -> 0 | P12: 0
A13: 9 | B13: 9 | E13: Premi Penjaminan Ulang | F13: 15188327378 | G13: 0 | H13: 314963836 | I13: 664280590 | J13: 11526814963 | K13: =SUM(F13:J13) -> 27694386767 | L13: 9.3492692e+09 | M13: 0 | N13: 3.5012192e+09 | O13: =SUM(L13:N13) -> 1.2850488e+10 | P13: =O13/K13 -> 0.46401058
C14: Y2 | E14: IMBAL JASA PENJAMINAN BERSIH | F14: =F11-F12-F13 -> 153484507527 | G14: =G11-G12-G13 -> 0 | H14: =H11-H12-H13 -> 2279074636 | I14: =I11-I12-I13 -> 3787180451 | J14: =J11-J12-J13 -> 7893748666 | K14: =K11-K12-K13 -> 167444511280 | L14: =L11-L12-L13 -> 7.7056396e+10 | M14: =M11-M12-M13 -> 0 | ... O14: =O11-O12-O13 -> 1.019597e+11 | P14: =O14/K14 -> 0.60891637
C16: X2 | D16: BEBAN KLAIM
A17: 22 | B17: 13 | E17: Beban Klaim | F17: 115373687533 | G17: 8584555675 | H17: 75000000 | I17: 1271904226 | J17: 16228026979 | K17: =SUM(F17:J17) -> 141533174413 | L17: 6.2472544e+10 | M17: 6.790617e+08 | N17: 3.0437562e+10 | O17: =SUM(L17:N17) -> 9.3589167e+10 | P17: =O17/K17 -> 0.66125251
A18: 24 | B18: 14 | E18: Kenaikan (Penurunan) Cadangan Klaim | F18: 3434033608 | G18: -2934113950 | H18: 51649426 | I18: 87275286 | J18: 8568198213 | K18: =SUM(F18:J18) -> 9207042583 | L18: 1.1979626e+10 | M18: -1.6420494e+09 | N18: -1.2086151e+10 | O18: =SUM(L18:N18) -> -1.7485746e+09 | P18: =O18/K18 -> -0.18991708
A19: 32 | B19: 15 | E19: Pendapatan Subrogasi | F19: 38329244677 | G19: 6769350368 | H19: 22094493 | I19: 45084709 | J19: 16659323166 | K19: =SUM(F19:J19) -> 61825097413 | L19: 1.6502994e+10 | M19: 3.0560596e+09 | N19: 4.2118817e+09 | O19: =SUM(L19:N19) -> 2.3770936e+10 | P19: =O19/K19 -> 0.38448683
A20: 37 | B20: 16 | E20: Beban Komisi Netto | F20: 2396724198 | G20: 0 | H20: 54737539 | I20: 101532381 | J20: 1758987457 | K20: =SUM(F20:J20) -> 4311981575 | L20: 1.5270359e+09 | M20: 0 | N20: 5.0350954e+08 | O20: =SUM(L20:N20) -> 2.0305454e+09 | P20: =O20/K20 -> 0.47090773
C21: Y2 | E21: JUMLAH BEBAN KLAIM | F21: =F17+F18-F19-F20 -> 78081752266 | G21: =G17+G18-G19-G20 -> -1118908643 | H21: =H17+H18-H19-H20 -> 49817394 | I21: =I17+I18-I19-I20 -> 1212562422 | J21: =J17+J18-J19-J20 -> 6377914569 | K21: =K17+K18-K19-K20 -> 84603138008 | L21: =L17+L18-L19-L20 -> 5.6422139e+10 | M21: =M17+M18-M19-M20 -> -4.0190473e+09 | ... O21: =O17+O18-O19-O20 -> 6.6039112e+10 | P21: =O21/K21 -> 0.7805752
C23: X1 | D23: PENJAMINAN BERSIH | F23: =F14-F21 -> 75402755261 | G23: =G14-G21 -> 1118908643 | H23: =H14-H21 -> 2229257242 | I23: =I14-I21 -> 2574618029 | J23: =J14-J21 -> 1515834097 | K23: =K14-K21 -> 82841373272 | L23: =L14-L21 -> 2.0634256e+10 | M23: =M14-M21 -> 4.0190473e+09 | ... O23: =O14-O21 -> 3.5920592e+10 | P23: =O23/K23 -> 0.43360691
B25: 19 | C25: X1 | D25: PENDAPATAN INVESTASI BERSIH | O25: 0 | P25: 0
C27: X1 | D27: BEBAN USAHA
C28: X2 | E28: BEBAN KARYAWAN
A29: 94 | E29: Beban gaji karyawan | F29: 969596418 | G29: 0 | H29: 19882043 | I29: 25588713 | J29: 112590574 | K29: =SUM(F29:J29) -> 1127657748 | L29: 4.6431909e+08 | N29: 2.034509e+08 | O29: =SUM(L29:N29) -> 667769998 | P29: =O29/K29 -> 0.59217435
A30: 95 | E30: Beban lembur karyawan | F30: 30358275 | G30: 0 | H30: 622511 | I30: 801188 | J30: 3525235 | K30: =SUM(F30:J30) -> 35307209 | L30: 11683487 | N30: 5126852.6 | O30: =SUM(L30:N30) -> 16810340 | P30: =O30/K30 -> 0.47611636
A31: 96 | E31: Beban asuransi kesehatan karyawan | F31: 156401572 | G31: 0 | H31: 3207090 | I31: 4127609 | J31: 18161518 | K31: =SUM(F31:J31) -> 181897789 | L31: 4104850 | N31: 1395150 | O31: =SUM(L31:N31) -> 5500000 | P31: =O31/K31 -> 0.030236761
A32: 97 | E32: Beban asuransi jiwa karyawan | F32: 7165646 | G32: 0 | H32: 146935 | I32: 189109 | J32: 832083 | K32: =SUM(F32:J32) -> 8333773 | L32: 0 | N32: 0 | O32: =SUM(L32:N32) -> 0 | P32: =O32/K32 -> 0
A33: 100 | E33: Beban dana pensiun | F33: 113572620 | G33: 0 | H33: 2328861 | I33: 2997306 | J33: 13188174 | K33: =SUM(F33:J33) -> 132086961 | L33: 0 | N33: 0 | O33: =SUM(L33:N33) -> 0 | P33: =O33/K33 -> 0
A34: 101 | E34: Beban kompensasi kinerja karyawan | F34: 1048226553 | G34: 0 | H34: 21494392 | I34: 27663848 | J34: 121721190 | K34: =SUM(F34:J34) -> 1219105983 | L34: 6.6022275e+08 | N34: 2.8992602e+08 | O34: =SUM(L34:N34) -> 9.5014877e+08 | P34: =O34/K34 -> 0.7793816
A35: 102 | E35: Biaya jasa kini karyawan | F35: 0 | G35: 0 | H35: 0 | I35: 0 | J35: 0 | K35: =SUM(F35:J35) -> 0 | L35: 0 | N35: 0 | O35: =SUM(L35:N35) -> 0 | P35: 0
A36: 103 | E36: Biaya jasa lalu karyawan | F36: 0 | G36: 0 | H36: 0 | I36: 0 | J36: 0 | K36: =SUM(F36:J36) -> 0 | L36: 0 | N36: 0 | O36: =SUM(L36:N36) -> 0 | P36: 0
A37: 104 | E37: Bunga atas imbalan pasca kerja karyawan | F37: 171733351 | G37: 0 | H37: 3521475 | I37: 4532231 | J37: 19941861 | K37: =SUM(F37:J37) -> 199728918 | L37: 0 | N37: 0 | O37: =SUM(L37:N37) -> 0 | P37: =O37/K37 -> 0
A38: 105 | E38: Beban BPJS kesehatan karyawan | F38: 43586002 | G38: 0 | H38: 893752 | I38: 1150282 | J38: 5061253 | K38: =SUM(F38:J38) -> 50691289 | L38: 0 | N38: 0 | O38: =SUM(L38:N38) -> 0 | P38: =O38/K38 -> 0
A39: 106 | E39: Beban BPJS jaminan hari tua karyawan | F39: 61831059 | G39: 0 | H39: 1267876 | I39: 1631789 | J39: 7179889 | K39: =SUM(F39:J39) -> 71910613 | L39: 0 | N39: 0 | O39: =SUM(L39:N39) -> 0 | P39: =O39/K39 -> 0
A40: 107 | E40: Beban BPJS jaminan kecelakaan kerja dan jaminan kematian karyawan | F40: 8973711 | G40: 0 | H40: 184010 | I40: 236826 | J40: 1042037 | K40: =SUM(F40:J40) -> 10436584 | L40: 0 | N40: 0 | O40: =SUM(L40:N40) -> 0 | P40: =O40/K40 -> 0
A41: 108 | E41: Beban BPJS jaminan pensiun karyawan | F41: 20792745 | G41: 0 | H41: 426365 | I41: 548743 | J41: 2414476 | K41: =SUM(F41:J41) -> 24182329 | L41: 0 | N41: 0 | O41: =SUM(L41:N41) -> 0 | P41: =O41/K41 -> 0
A42: 109 | E42: Beban tunjangan hari raya karyawan | F42: 139469311 | G42: 0 | H42: 2859886 | I42: 3680748 | J42: 16195326 | K42: =SUM(F42:J42) -> 162205271 | L42: 1.9941911e+08 | N42: 91208692 | O42: =SUM(L42:N42) -> 2.906278e+08 | P42: =O42/K42 -> 1.7917285
A43: 110 | E43: Beban tunjangan PPh 21 karyawan | F43: 1113365698 | G43: 0 | H43: 22830101 | I43: 29382941 | J43: 129285217 | K43: =SUM(F43:J43) -> 1294863957 | L43: 1.4698206e+08 | N43: 74709037 | O43: =SUM(L43:N43) -> 2.2169109e+08 | P43: =O43/K43 -> 0.17120802
A44: 111 | E44: Beban tunjangan transportasi karyawan | F44: 29986962 | G44: 0 | H44: 614897 | I44: 791389 | J44: 3482118 | K44: =SUM(F44:J44) -> 34875366 | L44: 27794500 | N44: 12205500 | O44: =SUM(L44:N44) -> 40000000 | P44: =O44/K44 -> 1.1469414
A45: 112 | E45: Beban tunjangan jabatan | F45: 707805475 | G45: 0 | H45: 14513893 | I45: 18679762 | J45: 82191129 | K45: =SUM(F45:J45) -> 823190259 | L45: 3.0486689e+08 | N45: 1.3384978e+08 | O45: =SUM(L45:N45) -> 4.3871667e+08 | P45: =O45/K45 -> 0.53294686
A46: 113 | E46: Beban tunjangan cuti besar | F46: 14274196 | G46: 0 | H46: 292699 | I46: 376712 | J46: 1657535 | K46: =SUM(F46:J46) -> 16601142 | L46: 0 | N46: 0 | O46: =SUM(L46:N46) -> 0 | P46: =O46/K46 -> 0
A47: 114 | E47: Beban tunjangan cuti tahunan | F47: 136952980 | G47: 0 | H47: 2808287 | I47: 3614339 | J47: 15903127 | K47: =SUM(F47:J47) -> 159278733 | L47: 0 | N47: 0 | O47: =SUM(L47:N47) -> 0 | P47: =O47/K47 -> 0
...

Sheet MADIUN
D1: PT JAMKRINDO KANWIL SURABAYA
D2: LABA RUGI RKA TAHUN 2026
O4: =#REF! -> #REF!
D5: URAIAN | F5: KANCA MADIUN | L5: REALISASI KANCA MADIUN | P5: %
F6: KUR | G6: PEN | H6: KBG/SURETYSHIP | I6: KONSUMTIF | J6: PRODUKTIF | K6: TOTAL | L6: KUR | M6: PEN | N6: NON KUR | O6: TOTAL | P6: %
C8: X1 | D8: VOLUME | F8: 4373360134287 | G8: 0 | H8: 596979491872 | I8: 429946561406 | J8: 797362922440 | K8: =SUM(F8:J8) -> 6197649110005 | L8: 3.1812747e+12 | N8: 2.4773032e+11 | O8: =SUM(L8:N8) -> 3.429005e+12 | P8: =O8/K8 -> 0.55327511
C10: X2 | D10: PENDAPATAN PENJAMINAN
A11: 7 | B11: 8 | E11: Imbal Jasa Penjaminan Bruto | F11: 158130782723 | G11: 0 | H11: 1945528854 | I11: 4173244726 | J11: 18113455973 | K11: =SUM(F11:J11) -> 182363012276 | L11: 9.1722602e+10 | M11: 400000 | N11: 3.6449675e+10 | O11: =SUM(L11:N11) -> 1.2817268e+11 | P11: =O11/K11 -> 0.7028436
A12: 12 | B12: 10 | E12: Restitusi penjaminan kredit | F12: 0 | G12: 0 | H12: 0 | I12: 0 | J12: 0 | K12: =SUM(F12:J12) -> 0 | L12: 0 | M12: 0 | N12: 0 | O12: =SUM(L12:N12) -> 0 | P12: 0
A13: 9 | B13: 9 | E13: Premi Penjaminan Ulang | F13: 14239056917 | G13: 0 | H13: 236222877 | I13: 622763053 | J13: 10794828562 | K13: =SUM(F13:J13) -> 25892871409 | L13: 9.8884319e+09 | M13: 0 | N13: 4.6307741e+09 | O13: =SUM(L13:N13) -> 1.4519206e+10 | P13: =O13/K13 -> 0.56074144
C14: Y2 | E14: IMBAL JASA PENJAMINAN BERSIH | F14: =F11-F12-F13 -> 143891725806 | G14: =G11-G12-G13 -> 0 | H14: =H11-H12-H13 -> 1709305977 | I14: =I11-I12-I13 -> 3550481673 | J14: =J11-J12-J13 -> 7318627411 | K14: =K11-K12-K13 -> 156470140867 | L14: =L11-L12-L13 -> 8.183417e+10 | M14: =M11-M12-M13 -> 400000 | ... O14: =O11-O12-O13 -> 1.1365347e+11 | P14: =O14/K14 -> 0.72635884
C16: X2 | D16: BEBAN KLAIM
A17: 22 | B17: 13 | E17: Beban Klaim | F17: 114016714018 | G17: 862699986 | H17: 65000000 | I17: 681243458 | J17: 6355201369 | K17: =SUM(F17:J17) -> 121980858831 | L17: 2.4497858e+10 | M17: 1050000000 | N17: 2.5627569e+10 | O17: =SUM(L17:N17) -> 5.1175427e+10 | P17: =O17/K17 -> 0.41953654
A18: 24 | B18: 14 | E18: Kenaikan (Penurunan) Cadangan Klaim | F18: 1226655107 | G18: -1050000000 | H18: 17700890 | I18: 0 | J18: 7006457653 | K18: =SUM(F18:J18) -> 7200813650 | L18: 37858644394 | M18: -1050000000 | N18: 11324597939 | O18: =SUM(L18:N18) -> 48133242333 | P18: =O18/K18 -> 6.6844172
A19: 32 | B19: 15 | E19: Pendapatan Subrogasi | F19: 14796402193 | G19: 1780216045 | H19: 10434947 | I19: 21292932 | J19: 6451123904 | K19: =SUM(F19:J19) -> 23059470021 | L19: 9.4424025e+09 | M19: 42441861 | N19: 3.1137272e+09 | O19: =SUM(L19:N19) -> 1.2598572e+10 | P19: =O19/K19 -> 0.54635131
A20: 37 | B20: 16 | E20: Beban Komisi Netto | F20: 2246928935 | G20: 0 | H20: 41053154 | I20: 95186607 | J20: 1647108492 | K20: =SUM(F20:J20) -> 4030277188 | L20: 1.6269396e+09 | M20: 0 | N20: 6.6824481e+08 | O20: =SUM(L20:N20) -> 2.2951844e+09 | P20: =O20/K20 -> 0.56948549
C21: Y2 | E21: JUMLAH BEBAN KLAIM | F21: =F17+F18-F19-F20 -> 98200037997 | G21: =G17+G18-G19-G20 -> -1967516059 | H21: =H17+H18-H19-H20 -> 31212789 | I21: =I17+I18-I19-I20 -> 564763919 | J21: =J17+J18-J19-J20 -> 5263426626 | K21: =K17+K18-K19-K20 -> 102091925272 | L21: =L17+L18-L19-L20 -> 5.128716e+10 | M21: =M17+M18-M19-M20 -> -42441861 | ... O21: =O17+O18-O19-O20 -> 8.4414913e+10 | P21: =O21/K21 -> 0.82685201
C23: X1 | D23: PENJAMINAN BERSIH | F23: =F14-F21 -> 45691687809 | G23: =G14-G21 -> 1967516059 | H23: =H14-H21 -> 1678093188 | I23: =I14-I21 -> 2985717754 | J23: =J14-J21 -> 2055200785 | K23: =K14-K21 -> 54378215595 | L23: =L14-L21 -> 3.054701e+10 | M23: =M14-M21 -> 42841861 | ... O23: =O14-O21 -> 2.9238557e+10 | P23: =O23/K23 -> 0.5376888
B25: 19 | C25: X1 | D25: PENDAPATAN INVESTASI BERSIH | F25: 0 | G25: 0 | H25: 0 | I25: 0 | J25: 0 | K25: 0 | O25: 0 | P25: 0
C27: X1 | D27: BEBAN USAHA
C28: X2 | E28: BEBAN KARYAWAN
A29: 94 | E29: Beban gaji karyawan | F29: 1050396120 | G29: 0 | H29: 21538880 | I29: 27721105 | J29: 121973122 | K29: =SUM(F29:J29) -> 1221629227 | L29: 4.5728931e+08 | N29: 2.0017423e+08 | O29: =SUM(L29:N29) -> 657463540 | P29: =O29/K29 -> 0.53818583
A30: 95 | E30: Beban lembur karyawan | F30: 20238850 | G30: 0 | H30: 415007 | I30: 534125 | J30: 2350157 | K30: =SUM(F30:J30) -> 23538139 | L30: 13343676 | N30: 5285771 | O30: =SUM(L30:N30) -> 18629447 | P30: =O30/K30 -> 0.79145794
A31: 96 | E31: Beban asuransi kesehatan karyawan | F31: 132339791 | G31: 0 | H31: 2713691 | I31: 3492592 | J31: 15367438 | K31: =SUM(F31:J31) -> 153913512 | L31: 6261080 | N31: 2538920 | O31: =SUM(L31:N31) -> 8800000 | P31: =O31/K31 -> 0.057174967
A32: 97 | E32: Beban asuransi jiwa karyawan | F32: 6063239 | G32: 0 | H32: 124330 | I32: 160016 | J32: 704070 | K32: =SUM(F32:J32) -> 7051655 | L32: 0 | N32: 0 | O32: =SUM(L32:N32) -> 0 | P32: =O32/K32 -> 0
