Workbook

Sheet KORPORAT KANWIL
D1: PT JAMKRINDO KANWIL SURABAYA
D2: LABA RUGI RKA TAHUN 2026
D5: URAIAN | F5: KORPORAT WILAYAH SURABAYA | L5: REALISASI KORPORAT KANWIL SURABAYA | S5: %
F6: KUR | G6: PEN | H6: KBG/SURETYSHIP | I6: KONSUMTIF | J6: PRODUKTIF | K6: TOTAL | L6: KUR | M6: PEN | N6: KBG/SURETYSHIP | O6: KONSUMTIF | P6: PRODUKTIF | Q6: NON KUR | R6: TOTAL | S6: %
F7: (a) | G7: (b) | H7: (c) | I7: (d) | J7: (e) | K7: (f) | L7: (g) | M7: (h) | N7: (i) | O7: (j) | P7: (k) | Q7: (l)=i+j+k | R7: (m) | S7: (n)=m/f
C9: X1 | D9: VOLUME | F9: =KANWIL!F9+SURABAYA!F9+KEDIRI!F9+MALANG!F9+MADIUN!F9+BANYUWANGI!F9 -> 29155734228583 | G9: =KANWIL!G9+SURABAYA!G9+KEDIRI!G9+MALANG!G9+MADIUN!G9+BANYUWANGI!G9 -> 0 | H9: =KANWIL!H9+SURABAYA!H9+KEDIRI!H9+MALANG!H9+MADIUN!H9+BANYUWANGI!H9 -> 6633105465239 | I9: =KANWIL!I9+SURABAYA!I9+KEDIRI!I9+MALANG!I9+MADIUN!I9+BANYUWANGI!I9 -> 2866310409375 | J9: =KANWIL!J9+SURABAYA!J9+KEDIRI!J9+MALANG!J9+MADIUN!J9+BANYUWANGI!J9 -> 5889752816264 | K9: =SUM(F9:J9) -> 44544902919461
C11: X2 | D11: PENDAPATAN PENJAMINAN
A12: 7 | B12: 8 | E12: Imbal Jasa Penjaminan Bruto | F12: =KANWIL!F12+SURABAYA!F12+KEDIRI!F12+MALANG!F12+MADIUN!F12+BANYUWANGI!F12 -> 1054205218156 | G12: =KANWIL!G12+SURABAYA!G12+KEDIRI!G12+MALANG!G12+MADIUN!G12+BANYUWANGI!G12 -> 0 | H12: =KANWIL!H12+SURABAYA!H12+KEDIRI!H12+MALANG!H12+MADIUN!H12+BANYUWANGI!H12 -> 21616987266 | I12: =KANWIL!I12+SURABAYA!I12+KEDIRI!I12+MALANG!I12+MADIUN!I12+BANYUWANGI!I12 -> 27821631504 | J12: =KANWIL!J12+SURABAYA!J12+KEDIRI!J12+MALANG!J12+MADIUN!J12+BANYUWANGI!J12 -> 122415438555 | K12: =SUM(F12:J12) -> 1226059275481 | L12: =KANWIL!L12+SURABAYA!L12+KEDIRI!L12+MALANG!L12+MADIUN!L12+BANYUWANGI!L12 -> 5.455123e+11 | M12: =KANWIL!M12+SURABAYA!M12+KEDIRI!M12+MALANG!M12+MADIUN!M12+BANYUWANGI!M12 -> 400000 | N12: =KANWIL!N12+SURABAYA!N12+KEDIRI!N12+MALANG!N12+MADIUN!N12+BANYUWANGI!N12 -> 5.6910708e+09 | O12: =KANWIL!O12+SURABAYA!O12+KEDIRI!O12+MALANG!O12+MADIUN!O12+BANYUWANGI!O12 -> 1.0105604e+10 | P12: =KANWIL!P12+SURABAYA!P12+KEDIRI!P12+MALANG!P12+MADIUN!P12+BANYUWANGI!P12 -> 1.9253154e+11 | Q12: =N12+O12+P12 -> 2.0832822e+11 | R12: =SUM(L12:P12) -> 7.5384092e+11 | S12: =IF(K12=0,0,R12/K12) -> 0.61484867
A13: 12 | B13: 10 | E13: Restitusi penjaminan kredit | F13: =KANWIL!F13+SURABAYA!F13+KEDIRI!F13+MALANG!F13+MADIUN!F13+BANYUWANGI!F13 -> 0 | G13: =KANWIL!G13+SURABAYA!G13+KEDIRI!G13+MALANG!G13+MADIUN!G13+BANYUWANGI!G13 -> 0 | H13: =KANWIL!H13+SURABAYA!H13+KEDIRI!H13+MALANG!H13+MADIUN!H13+BANYUWANGI!H13 -> 0 | I13: =KANWIL!I13+SURABAYA!I13+KEDIRI!I13+MALANG!I13+MADIUN!I13+BANYUWANGI!I13 -> 0 | J13: =KANWIL!J13+SURABAYA!J13+KEDIRI!J13+MALANG!J13+MADIUN!J13+BANYUWANGI!J13 -> 0 | K13: =SUM(F13:J13) -> 0
A14: 9 | B14: 9 | E14: Premi Penjaminan Ulang | F14: =KANWIL!F14+SURABAYA!F14+KEDIRI!F14+MALANG!F14+MADIUN!F14+BANYUWANGI!F14 -> 94927046114 | G14: =KANWIL!G14+SURABAYA!G14+KEDIRI!G14+MALANG!G14+MADIUN!G14+BANYUWANGI!G14 -> 0 | H14: =KANWIL!H14+SURABAYA!H14+KEDIRI!H14+MALANG!H14+MADIUN!H14+BANYUWANGI!H14 -> 2624698636 | I14: =KANWIL!I14+SURABAYA!I14+KEDIRI!I14+MALANG!I14+MADIUN!I14+BANYUWANGI!I14 -> 4151753688 | J14: =KANWIL!J14+SURABAYA!J14+KEDIRI!J14+MALANG!J14+MADIUN!J14+BANYUWANGI!J14 -> 72171043143 | K14: =SUM(F14:J14) -> 173874541581 | L14: =KANWIL!L14+SURABAYA!L14+KEDIRI!L14+MALANG!L14+MADIUN!L14+BANYUWANGI!L14 -> 5.776021e+10 | N14: =KANWIL!N14+SURABAYA!N14+KEDIRI!N14+MALANG!N14+MADIUN!N14+BANYUWANGI!N14 -> 5.8801525e+08 | O14: =KANWIL!O14+SURABAYA!O14+KEDIRI!O14+MALANG!O14+MADIUN!O14+BANYUWANGI!O14 -> 1.1248546e+09 | P14: =KANWIL!P14+SURABAYA!P14+KEDIRI!P14+MALANG!P14+MADIUN!P14+BANYUWANGI!P14 -> 2.5041922e+10 | Q14: =N14+O14+P14 -> 2.6754792e+10 | R14: =SUM(L14:P14) -> 8.4515001e+10 | S14: =IF(K14=0,0,R14/K14) -> 0.48606887
C15: Y2 | E15: IMBAL JASA PENJAMINAN BERSIH | F15: =F12-F13-F14 -> 959278172042 | G15: =G12-G13-G14 -> 0 | H15: =H12-H13-H14 -> 18992288630 | I15: =I12-I13-I14 -> 23669877816 | J15: =J12-J13-J14 -> 50244395412 | K15: =K12-K13-K14 -> 1052184733900 | L15: =L12-L13-L14 -> 4.877521e+11 | M15: =M12-M13-M14 -> 400000 | ... R15: =R12-R13-R14 -> 6.6932592e+11 | S15: =IF(K15=0,0,R15/K15) -> 0.63612966
C16: 22
C17: X2 | D17: BEBAN KLAIM
A18: 22 | B18: 13 | E18: Beban Klaim | F18: =KANWIL!F18+SURABAYA!F18+KEDIRI!F18+MALANG!F18+MADIUN!F18+BANYUWANGI!F18 -> 809802922564 | G18: =KANWIL!G18+SURABAYA!G18+KEDIRI!G18+MALANG!G18+MADIUN!G18+BANYUWANGI!G18 -> 34965416239 | H18: =KANWIL!H18+SURABAYA!H18+KEDIRI!H18+MALANG!H18+MADIUN!H18+BANYUWANGI!H18 -> 5658069138 | I18: =KANWIL!I18+SURABAYA!I18+KEDIRI!I18+MALANG!I18+MADIUN!I18+BANYUWANGI!I18 -> 9169963227 | J18: =KANWIL!J18+SURABAYA!J18+KEDIRI!J18+MALANG!J18+MADIUN!J18+BANYUWANGI!J18 -> 102940478187 | K18: =SUM(F18:J18) -> 962536849355 | L18: =KANWIL!L18+SURABAYA!L18+KEDIRI!L18+MALANG!L18+MADIUN!L18+BANYUWANGI!L18 -> 3.3259949e+11 | M18: =KANWIL!M18+SURABAYA!M18+KEDIRI!M18+MALANG!M18+MADIUN!M18+BANYUWANGI!M18 -> 6.5023855e+09 | N18: =KANWIL!N18+SURABAYA!N18+KEDIRI!N18+MALANG!N18+MADIUN!N18+BANYUWANGI!N18 -> 2.1865236e+09 | O18: =KANWIL!O18+SURABAYA!O18+KEDIRI!O18+MALANG!O18+MADIUN!O18+BANYUWANGI!O18 -> 9.623651e+08 | P18: =KANWIL!P18+SURABAYA!P18+KEDIRI!P18+MALANG!P18+MADIUN!P18+BANYUWANGI!P18 -> 1.7894665e+11 | Q18: =N18+O18+P18 -> 1.8209554e+11 | R18: =SUM(L18:P18) -> 5.2119741e+11 | S18: =IF(K18=0,0,R18/K18) -> 0.54148307
A19: 24 | B19: 14 | E19: Kenaikan (Penurunan) Cadangan Klaim | F19: =KANWIL!F19+SURABAYA!F19+KEDIRI!F19+MALANG!F19+MADIUN!F19+BANYUWANGI!F19 -> 9715485499 | G19: =KANWIL!G19+SURABAYA!G19+KEDIRI!G19+MALANG!G19+MADIUN!G19+BANYUWANGI!G19 -> -10323848200 | H19: =KANWIL!H19+SURABAYA!H19+KEDIRI!H19+MALANG!H19+MADIUN!H19+BANYUWANGI!H19 -> 677983388 | I19: =KANWIL!I19+SURABAYA!I19+KEDIRI!I19+MALANG!I19+MADIUN!I19+BANYUWANGI!I19 -> 397223586 | J19: =KANWIL!J19+SURABAYA!J19+KEDIRI!J19+MALANG!J19+MADIUN!J19+BANYUWANGI!J19 -> 31382109977 | K19: =SUM(F19:J19) -> 31848954250 | L19: =KANWIL!L19+SURABAYA!L19+KEDIRI!L19+MALANG!L19+MADIUN!L19+BANYUWANGI!L19 -> 7.9489583e+10 | M19: =KANWIL!M19+SURABAYA!M19+KEDIRI!M19+MALANG!M19+MADIUN!M19+BANYUWANGI!M19 -> -9.0317836e+09 | N19: =KANWIL!N19+SURABAYA!N19+KEDIRI!N19+MALANG!N19+MADIUN!N19+BANYUWANGI!N19 -> 0 | O19: =KANWIL!O19+SURABAYA!O19+KEDIRI!O19+MALANG!O19+MADIUN!O19+BANYUWANGI!O19 -> 0 | P19: =KANWIL!P19+SURABAYA!P19+KEDIRI!P19+MALANG!P19+MADIUN!P19+BANYUWANGI!P19 -> 0 | Q19: =KANWIL!Q19+SURABAYA!Q19+KEDIRI!Q19+MALANG!Q19+MADIUN!Q19+BANYUWANGI!Q19 -> 1.5236457e+10 | R19: =SUM(L19:Q19) -> 8.5694256e+10 | S19: =IF(K19=0,0,R19/K19) -> 2.6906458
A20: 32 | B20: 15 | E20: Pendapatan Subrogasi | F20: =KANWIL!F20+SURABAYA!F20+KEDIRI!F20+MALANG!F20+MADIUN!F20+BANYUWANGI!F20 -> 208858906675 | G20: =KANWIL!G20+SURABAYA!G20+KEDIRI!G20+MALANG!G20+MADIUN!G20+BANYUWANGI!G20 -> 34248988772 | H20: =KANWIL!H20+SURABAYA!H20+KEDIRI!H20+MALANG!H20+MADIUN!H20+BANYUWANGI!H20 -> 147999934 | I20: =KANWIL!I20+SURABAYA!I20+KEDIRI!I20+MALANG!I20+MADIUN!I20+BANYUWANGI!I20 -> 301999866 | J20: =KANWIL!J20+SURABAYA!J20+KEDIRI!J20+MALANG!J20+MADIUN!J20+BANYUWANGI!J20 -> 83496959312 | K20: =SUM(F20:J20) -> 327054854559 | L20: =KANWIL!L20+SURABAYA!L20+KEDIRI!L20+MALANG!L20+MADIUN!L20+BANYUWANGI!L20 -> 1.0831009e+11 | M20: =KANWIL!M20+SURABAYA!M20+KEDIRI!M20+MALANG!M20+MADIUN!M20+BANYUWANGI!M20 -> 1.2937903e+10 | O20: =KANWIL!O20+SURABAYA!O20+KEDIRI!O20+MALANG!O20+MADIUN!O20+BANYUWANGI!O20 -> 1.0136337e+08 | P20: =KANWIL!P20+SURABAYA!P20+KEDIRI!P20+MALANG!P20+MADIUN!P20+BANYUWANGI!P20 -> 4.6403826e+10 | Q20: =KANWIL!Q20+SURABAYA!Q20+KEDIRI!Q20+MALANG!Q20+MADIUN!Q20+BANYUWANGI!Q20 -> 4.0738256e+10 | R20: 1.6198625e+11 | S20: =IF(K20=0,0,R20/K20) -> 0.49528772
A21: 37 | B21: 16 | E21: Beban Komisi Netto | F21: =KANWIL!F21+SURABAYA!F21+KEDIRI!F21+MALANG!F21+MADIUN!F21+BANYUWANGI!F21 -> 14979526236 | G21: =KANWIL!G21+SURABAYA!G21+KEDIRI!G21+MALANG!G21+MADIUN!G21+BANYUWANGI!G21 -> 0 | H21: =KANWIL!H21+SURABAYA!H21+KEDIRI!H21+MALANG!H21+MADIUN!H21+BANYUWANGI!H21 -> 456146159 | I21: =KANWIL!I21+SURABAYA!I21+KEDIRI!I21+MALANG!I21+MADIUN!I21+BANYUWANGI!I21 -> 634577379 | J21: =KANWIL!J21+SURABAYA!J21+KEDIRI!J21+MALANG!J21+MADIUN!J21+BANYUWANGI!J21 -> 11015252139 | K21: =SUM(F21:J21) -> 27085501913 | L21: =KANWIL!L21+SURABAYA!L21+KEDIRI!L21+MALANG!L21+MADIUN!L21+BANYUWANGI!L21 -> 9.4954242e+09 | N21: =KANWIL!N21+SURABAYA!N21+KEDIRI!N21+MALANG!N21+MADIUN!N21+BANYUWANGI!N21 -> 89860144 | O21: =KANWIL!O21+SURABAYA!O21+KEDIRI!O21+MALANG!O21+MADIUN!O21+BANYUWANGI!O21 -> -11303879 | P21: =KANWIL!P21+SURABAYA!P21+KEDIRI!P21+MALANG!P21+MADIUN!P21+BANYUWANGI!P21 -> 3.6332457e+09 | Q21: =N21+O21+P21 -> 3.711802e+09 | R21: =SUM(L21:P21) -> 1.3207226e+10 | S21: =IF(K21=0,0,R21/K21) -> 0.48761239
C22: Y2 | E22: JUMLAH BEBAN KLAIM | F22: =F18+F19-F20-F21 -> 595679975152 | G22: =G18+G19-G20-G21 -> -9607420733 | H22: =H18+H19-H20-H21 -> 5731906433 | I22: =I18+I19-I20-I21 -> 8630609568 | J22: =J18+J19-J20-J21 -> 39810376713 | K22: =K18+K19-K20-K21 -> 640245447133 | L22: =L18+L19-L20-L21 -> 2.9428355e+11 | M22: =M18+M19-M20-M21 -> -1.5467301e+10 | ... R22: =R18+R19-R20-R21 -> 4.3169819e+11 | S22: =IF(K22=0,0,R22/K22) -> 0.67426983
C24: X1 | D24: PENJAMINAN BERSIH | F24: =F15-F22 -> 363598196890 | G24: =G15-G22 -> 9607420733 | H24: =H15-H22 -> 13260382197 | I24: =I15-I22 -> 15039268248 | J24: =J15-J22 -> 10434018699 | K24: =K15-K22 -> 411939286767 | L24: =L15-L22 -> 1.9346854e+11 | M24: =M15-M22 -> 1.5467701e+10 | ... R24: =R15-R22 -> 2.3762773e+11 | S24: =IF(K24=0,0,R24/K24) -> 0.57685134
B26: 19 | C26: X1 | D26: PENDAPATAN INVESTASI BERSIH | F26: 0 | G26: 0 | H26: 0 | I26: 0 | J26: 0 | K26: 0
C28: X1 | D28: BEBAN USAHA
C29: X2 | E29: BEBAN KARYAWAN
A30: 94 | E30: Beban gaji karyawan | F30: =KANWIL!F30+SURABAYA!F30+KEDIRI!F30+MALANG!F30+MADIUN!F30+BANYUWANGI!F30 -> 8079970152 | G30: =KANWIL!G30+SURABAYA!G30+KEDIRI!G30+MALANG!G30+MADIUN!G30+BANYUWANGI!G30 -> 0 | H30: =KANWIL!H30+SURABAYA!H30+KEDIRI!H30+MALANG!H30+MADIUN!H30+BANYUWANGI!H30 -> 165683692 | I30: =KANWIL!I30+SURABAYA!I30+KEDIRI!I30+MALANG!I30+MADIUN!I30+BANYUWANGI!I30 -> 213239272 | J30: =KANWIL!J30+SURABAYA!J30+KEDIRI!J30+MALANG!J30+MADIUN!J30+BANYUWANGI!J30 -> 938254784 | K30: =SUM(F30:J30) -> 9397147900 | L30: =KANWIL!L30+SURABAYA!L30+KEDIRI!L30+MALANG!L30+MADIUN!L30+BANYUWANGI!L30 -> 3.8425372e+09 | N30: =KANWIL!N30+SURABAYA!N30+KEDIRI!N30+MALANG!N30+MADIUN!N30+BANYUWANGI!N30 -> 45827998 | O30: =KANWIL!O30+SURABAYA!O30+KEDIRI!O30+MALANG!O30+MADIUN!O30+BANYUWANGI!O30 -> 87565693 | P30: =KANWIL!P30+SURABAYA!P30+KEDIRI!P30+MALANG!P30+MADIUN!P30+BANYUWANGI!P30 -> 1.55286e+09 | Q30: =N30+O30+P30 -> 1.6862537e+09 | R30: =SUM(L30:P30) -> 5.528791e+09 | S30: =IF(K30=0,0,R30/K30) -> 0.58834777
A31: 95 | E31: Beban lembur karyawan | F31: =KANWIL!F31+SURABAYA!F31+KEDIRI!F31+MALANG!F31+MADIUN!F31+BANYUWANGI!F31 -> 252985625 | G31: =KANWIL!G31+SURABAYA!G31+KEDIRI!G31+MALANG!G31+MADIUN!G31+BANYUWANGI!G31 -> 0 | H31: =KANWIL!H31+SURABAYA!H31+KEDIRI!H31+MALANG!H31+MADIUN!H31+BANYUWANGI!H31 -> 5187593 | I31: =KANWIL!I31+SURABAYA!I31+KEDIRI!I31+MALANG!I31+MADIUN!I31+BANYUWANGI!I31 -> 6676569 | J31: =KANWIL!J31+SURABAYA!J31+KEDIRI!J31+MALANG!J31+MADIUN!J31+BANYUWANGI!J31 -> 29376961 | K31: =SUM(F31:J31) -> 294226748 | L31: =KANWIL!L31+SURABAYA!L31+KEDIRI!L31+MALANG!L31+MADIUN!L31+BANYUWANGI!L31 -> 1.0881745e+08 | N31: =KANWIL!N31+SURABAYA!N31+KEDIRI!N31+MALANG!N31+MADIUN!N31+BANYUWANGI!N31 -> 1456717.1 | O31: =KANWIL!O31+SURABAYA!O31+KEDIRI!O31+MALANG!O31+MADIUN!O31+BANYUWANGI!O31 -> 2434899 | P31: =KANWIL!P31+SURABAYA!P31+KEDIRI!P31+MALANG!P31+MADIUN!P31+BANYUWANGI!P31 -> 42718799 | Q31: =N31+O31+P31 -> 46610415 | R31: =SUM(L31:P31) -> 1.5542786e+08 | S31: =IF(K31=0,0,R31/K31) -> 0.52825877
A32: 96 | E32: Beban asuransi kesehatan karyawan | F32: =KANWIL!F32+SURABAYA!F32+KEDIRI!F32+MALANG!F32+MADIUN!F32+BANYUWANGI!F32 -> 1203089015 | G32: =KANWIL!G32+SURABAYA!G32+KEDIRI!G32+MALANG!G32+MADIUN!G32+BANYUWANGI!G32 -> 0 | H32: =KANWIL!H32+SURABAYA!H32+KEDIRI!H32+MALANG!H32+MADIUN!H32+BANYUWANGI!H32 -> 24669920 | I32: =KANWIL!I32+SURABAYA!I32+KEDIRI!I32+MALANG!I32+MADIUN!I32+BANYUWANGI!I32 -> 31750838 | J32: =KANWIL!J32+SURABAYA!J32+KEDIRI!J32+MALANG!J32+MADIUN!J32+BANYUWANGI!J32 -> 139703984 | K32: =SUM(F32:J32) -> 1399213757 | L32: =KANWIL!L32+SURABAYA!L32+KEDIRI!L32+MALANG!L32+MADIUN!L32+BANYUWANGI!L32 -> 32771149 | N32: =KANWIL!N32+SURABAYA!N32+KEDIRI!N32+MALANG!N32+MADIUN!N32+BANYUWANGI!N32 -> 184268.97 | O32: =KANWIL!O32+SURABAYA!O32+KEDIRI!O32+MALANG!O32+MADIUN!O32+BANYUWANGI!O32 -> 722029.47 | P32: =KANWIL!P32+SURABAYA!P32+KEDIRI!P32+MALANG!P32+MADIUN!P32+BANYUWANGI!P32 -> 12331553 | Q32: =N32+O32+P32 -> 13237851 | R32: =SUM(L32:P32) -> 46009000 | S32: =IF(K32=0,0,R32/K32) -> 0.032882038
A33: 97 | E33: Beban asuransi jiwa karyawan | F33: =KANWIL!F33+SURABAYA!F33+KEDIRI!F33+MALANG!F33+MADIUN!F33+BANYUWANGI!F33 -> 55120357 | G33: =KANWIL!G33+SURABAYA!G33+KEDIRI!G33+MALANG!G33+MADIUN!G33+BANYUWANGI!G33 -> 0 | H33: =KANWIL!H33+SURABAYA!H33+KEDIRI!H33+MALANG!H33+MADIUN!H33+BANYUWANGI!H33 -> 1130269 | I33: =KANWIL!I33+SURABAYA!I33+KEDIRI!I33+MALANG!I33+MADIUN!I33+BANYUWANGI!I33 -> 1454687 | J33: =KANWIL!J33+SURABAYA!J33+KEDIRI!J33+MALANG!J33+MADIUN!J33+BANYUWANGI!J33 -> 6400635 | K33: =SUM(F33:J33) -> 64105948
A34: 100 | E34: Beban dana pensiun | F34: =KANWIL!F34+SURABAYA!F34+KEDIRI!F34+MALANG!F34+MADIUN!F34+BANYUWANGI!F34 -> 873635539 | G34: =KANWIL!G34+SURABAYA!G34+KEDIRI!G34+MALANG!G34+MADIUN!G34+BANYUWANGI!G34 -> 0 | H34: =KANWIL!H34+SURABAYA!H34+KEDIRI!H34+MALANG!H34+MADIUN!H34+BANYUWANGI!H34 -> 17914319 | I34: =KANWIL!I34+SURABAYA!I34+KEDIRI!I34+MALANG!I34+MADIUN!I34+BANYUWANGI!I34 -> 23056200 | J34: =KANWIL!J34+SURABAYA!J34+KEDIRI!J34+MALANG!J34+MADIUN!J34+BANYUWANGI!J34 -> 101447493 | K34: =SUM(F34:J34) -> 1016053551
A35: 101 | E35: Beban kompensasi kinerja karyawan | F35: =KANWIL!F35+SURABAYA!F35+KEDIRI!F35+MALANG!F35+MADIUN!F35+BANYUWANGI!F35 -> 9945044587 | G35: =KANWIL!G35+SURABAYA!G35+KEDIRI!G35+MALANG!G35+MADIUN!G35+BANYUWANGI!G35 -> 0 | H35: =KANWIL!H35+SURABAYA!H35+KEDIRI!H35+MALANG!H35+MADIUN!H35+BANYUWANGI!H35 -> 203927943 | I35: =KANWIL!I35+SURABAYA!I35+KEDIRI!I35+MALANG!I35+MADIUN!I35+BANYUWANGI!I35 -> 262460630 | J35: =KANWIL!J35+SURABAYA!J35+KEDIRI!J35+MALANG!J35+MADIUN!J35+BANYUWANGI!J35 -> 1154829224 | K35: =SUM(F35:J35) -> 11566262384 | L35: =KANWIL!L35+SURABAYA!L35+KEDIRI!L35+MALANG!L35+MADIUN!L35+BANYUWANGI!L35 -> 4.9904913e+09 | N35: =KANWIL!N35+SURABAYA!N35+KEDIRI!N35+MALANG!N35+MADIUN!N35+BANYUWANGI!N35 -> 60963588 | O35: =KANWIL!O35+SURABAYA!O35+KEDIRI!O35+MALANG!O35+MADIUN!O35+BANYUWANGI!O35 -> 1.1345645e+08 | P35: =KANWIL!P35+SURABAYA!P35+KEDIRI!P35+MALANG!P35+MADIUN!P35+BANYUWANGI!P35 -> 2.0170726e+09 | Q35: =N35+O35+P35 -> 2.1914926e+09 | R35: =SUM(L35:P35) -> 7.181984e+09 | S35: =IF(K35=0,0,R35/K35) -> 0.62094251
A36: 102 | E36: Biaya jasa kini karyawan | F36: =KANWIL!F36+SURABAYA!F36+KEDIRI!F36+MALANG!F36+MADIUN!F36+BANYUWANGI!F36 -> 0 | G36: =KANWIL!G36+SURABAYA!G36+KEDIRI!G36+MALANG!G36+MADIUN!G36+BANYUWANGI!G36 -> 0 | H36: =KANWIL!H36+SURABAYA!H36+KEDIRI!H36+MALANG!H36+MADIUN!H36+BANYUWANGI!H36 -> 0 | I36: =KANWIL!I36+SURABAYA!I36+KEDIRI!I36+MALANG!I36+MADIUN!I36+BANYUWANGI!I36 -> 0 | J36: =KANWIL!J36+SURABAYA!J36+KEDIRI!J36+MALANG!J36+MADIUN!J36+BANYUWANGI!J36 -> 0 | K36: =SUM(F36:J36) -> 0
A37: 103 | E37: Biaya jasa lalu karyawan | F37: =KANWIL!F37+SURABAYA!F37+KEDIRI!F37+MALANG!F37+MADIUN!F37+BANYUWANGI!F37 -> 0 | G37: =KANWIL!G37+SURABAYA!G37+KEDIRI!G37+MALANG!G37+MADIUN!G37+BANYUWANGI!G37 -> 0 | H37: =KANWIL!H37+SURABAYA!H37+KEDIRI!H37+MALANG!H37+MADIUN!H37+BANYUWANGI!H37 -> 0 | I37: =KANWIL!I37+SURABAYA!I37+KEDIRI!I37+MALANG!I37+MADIUN!I37+BANYUWANGI!I37 -> 0 | J37: =KANWIL!J37+SURABAYA!J37+KEDIRI!J37+MALANG!J37+MADIUN!J37+BANYUWANGI!J37 -> 0 | K37: =SUM(F37:J37) -> 0
A38: 104 | E38: Bunga atas imbalan pasca kerja karyawan | F38: =KANWIL!F38+SURABAYA!F38+KEDIRI!F38+MALANG!F38+MADIUN!F38+BANYUWANGI!F38 -> 1321025775 | G38: =KANWIL!G38+SURABAYA!G38+KEDIRI!G38+MALANG!G38+MADIUN!G38+BANYUWANGI!G38 -> 0 | H38: =KANWIL!H38+SURABAYA!H38+KEDIRI!H38+MALANG!H38+MADIUN!H38+BANYUWANGI!H38 -> 27088272 | I38: =KANWIL!I38+SURABAYA!I38+KEDIRI!I38+MALANG!I38+MADIUN!I38+BANYUWANGI!I38 -> 34863319 | J38: =KANWIL!J38+SURABAYA!J38+KEDIRI!J38+MALANG!J38+MADIUN!J38+BANYUWANGI!J38 -> 153398927 | K38: =SUM(F38:J38) -> 1536376293
A39: 105 | E39: Beban BPJS kesehatan karyawan | F39: =KANWIL!F39+SURABAYA!F39+KEDIRI!F39+MALANG!F39+MADIUN!F39+BANYUWANGI!F39 -> 335276936 | G39: =KANWIL!G39+SURABAYA!G39+KEDIRI!G39+MALANG!G39+MADIUN!G39+BANYUWANGI!G39 -> 0 | H39: =KANWIL!H39+SURABAYA!H39+KEDIRI!H39+MALANG!H39+MADIUN!H39+BANYUWANGI!H39 -> 6875015 | I39: =KANWIL!I39+SURABAYA!I39+KEDIRI!I39+MALANG!I39+MADIUN!I39+BANYUWANGI!I39 -> 8848326 | J39: =KANWIL!J39+SURABAYA!J39+KEDIRI!J39+MALANG!J39+MADIUN!J39+BANYUWANGI!J39 -> 38932718 | K39: =SUM(F39:J39) -> 389932995
A40: 106 | E40: Beban BPJS jaminan hari tua karyawan | F40: =KANWIL!F40+SURABAYA!F40+KEDIRI!F40+MALANG!F40+MADIUN!F40+BANYUWANGI!F40 -> 475623528 | G40: =KANWIL!G40+SURABAYA!G40+KEDIRI!G40+MALANG!G40+MADIUN!G40+BANYUWANGI!G40 -> 0 | H40: =KANWIL!H40+SURABAYA!H40+KEDIRI!H40+MALANG!H40+MADIUN!H40+BANYUWANGI!H40 -> 9752891 | I40: =KANWIL!I40+SURABAYA!I40+KEDIRI!I40+MALANG!I40+MADIUN!I40+BANYUWANGI!I40 -> 12552226 | J40: =KANWIL!J40+SURABAYA!J40+KEDIRI!J40+MALANG!J40+MADIUN!J40+BANYUWANGI!J40 -> 55229913 | K40: =SUM(F40:J40) -> 553158558
A41: 107 | E41: Beban BPJS jaminan kecelakaan kerja dan jaminan kematian karyawan | F41: =KANWIL!F41+SURABAYA!F41+KEDIRI!F41+MALANG!F41+MADIUN!F41+BANYUWANGI!F41 -> 69028547 | G41: =KANWIL!G41+SURABAYA!G41+KEDIRI!G41+MALANG!G41+MADIUN!G41+BANYUWANGI!G41 -> 0 | H41: =KANWIL!H41+SURABAYA!H41+KEDIRI!H41+MALANG!H41+MADIUN!H41+BANYUWANGI!H41 -> 1415464 | I41: =KANWIL!I41+SURABAYA!I41+KEDIRI!I41+MALANG!I41+MADIUN!I41+BANYUWANGI!I41 -> 1821739 | J41: =KANWIL!J41+SURABAYA!J41+KEDIRI!J41+MALANG!J41+MADIUN!J41+BANYUWANGI!J41 -> 8015669 | K41: =SUM(F41:J41) -> 80281419
A42: 108 | E42: Beban BPJS jaminan pensiun karyawan | F42: =KANWIL!F42+SURABAYA!F42+KEDIRI!F42+MALANG!F42+MADIUN!F42+BANYUWANGI!F42 -> 159944196 | G42: =KANWIL!G42+SURABAYA!G42+KEDIRI!G42+MALANG!G42+MADIUN!G42+BANYUWANGI!G42 -> 0 | H42: =KANWIL!H42+SURABAYA!H42+KEDIRI!H42+MALANG!H42+MADIUN!H42+BANYUWANGI!H42 -> 3279733 | I42: =KANWIL!I42+SURABAYA!I42+KEDIRI!I42+MALANG!I42+MADIUN!I42+BANYUWANGI!I42 -> 4221101 | J42: =KANWIL!J42+SURABAYA!J42+KEDIRI!J42+MALANG!J42+MADIUN!J42+BANYUWANGI!J42 -> 18572892 | K42: =SUM(F42:J42) -> 186017922
A43: 109 | E43: Beban tunjangan hari raya karyawan | F43: =KANWIL!F43+SURABAYA!F43+KEDIRI!F43+MALANG!F43+MADIUN!F43+BANYUWANGI!F43 -> 2027967651 | G43: =KANWIL!G43+SURABAYA!G43+KEDIRI!G43+MALANG!G43+MADIUN!G43+BANYUWANGI!G43 -> 0 | H43: =KANWIL!H43+SURABAYA!H43+KEDIRI!H43+MALANG!H43+MADIUN!H43+BANYUWANGI!H43 -> 41584457 | I43: =KANWIL!I43+SURABAYA!I43+KEDIRI!I43+MALANG!I43+MADIUN!I43+BANYUWANGI!I43 -> 53520289 | J43: =KANWIL!J43+SURABAYA!J43+KEDIRI!J43+MALANG!J43+MADIUN!J43+BANYUWANGI!J43 -> 235489774 | K43: =SUM(F43:J43) -> 2358562171 | L43: =KANWIL!L43+SURABAYA!L43+KEDIRI!L43+MALANG!L43+MADIUN!L43+BANYUWANGI!L43 -> 1.5073691e+09 | N43: =KANWIL!N43+SURABAYA!N43+KEDIRI!N43+MALANG!N43+MADIUN!N43+BANYUWANGI!N43 -> 19178717 | O43: =KANWIL!O43+SURABAYA!O43+KEDIRI!O43+MALANG!O43+MADIUN!O43+BANYUWANGI!O43 -> 35692602 | P43: =KANWIL!P43+SURABAYA!P43+KEDIRI!P43+MALANG!P43+MADIUN!P43+BANYUWANGI!P43 -> 6.3455689e+08 | Q43: =N43+O43+P43 -> 6.8942821e+08 | R43: =SUM(L43:P43) -> 2.1967973e+09 | S43: =IF(K43=0,0,R43/K43) -> 0.93141376
A44: 110 | E44: Beban tunjangan PPh 21 karyawan | F44: =KANWIL!F44+SURABAYA!F44+KEDIRI!F44+MALANG!F44+MADIUN!F44+BANYUWANGI!F44 -> 6863069834 | G44: =KANWIL!G44+SURABAYA!G44+KEDIRI!G44+MALANG!G44+MADIUN!G44+BANYUWANGI!G44 -> 0 | H44: =KANWIL!H44+SURABAYA!H44+KEDIRI!H44+MALANG!H44+MADIUN!H44+BANYUWANGI!H44 -> 140730562 | I44: =KANWIL!I44+SURABAYA!I44+KEDIRI!I44+MALANG!I44+MADIUN!I44+BANYUWANGI!I44 -> 181123936 | J44: =KANWIL!J44+SURABAYA!J44+KEDIRI!J44+MALANG!J44+MADIUN!J44+BANYUWANGI!J44 -> 796947017 | K44: =SUM(F44:J44) -> 7981871349 | L44: =KANWIL!L44+SURABAYA!L44+KEDIRI!L44+MALANG!L44+MADIUN!L44+BANYUWANGI!L44 -> 9.8119677e+08 | N44: =KANWIL!N44+SURABAYA!N44+KEDIRI!N44+MALANG!N44+MADIUN!N44+BANYUWANGI!N44 -> 11178206 | O44: =KANWIL!O44+SURABAYA!O44+KEDIRI!O44+MALANG!O44+MADIUN!O44+BANYUWANGI!O44 -> 28157712 | P44: =KANWIL!P44+SURABAYA!P44+KEDIRI!P44+MALANG!P44+MADIUN!P44+BANYUWANGI!P44 -> 4.3173176e+08 | Q44: =N44+O44+P44 -> 4.7106768e+08 | R44: =SUM(L44:P44) -> 1.4522645e+09 | S44: =IF(K44=0,0,R44/K44) -> 0.18194536
A45: 111 | E45: Beban tunjangan transportasi karyawan | F45: =KANWIL!F45+SURABAYA!F45+KEDIRI!F45+MALANG!F45+MADIUN!F45+BANYUWANGI!F45 -> 313456462 | G45: =KANWIL!G45+SURABAYA!G45+KEDIRI!G45+MALANG!G45+MADIUN!G45+BANYUWANGI!G45 -> 0 | H45: =KANWIL!H45+SURABAYA!H45+KEDIRI!H45+MALANG!H45+MADIUN!H45+BANYUWANGI!H45 -> 6427576 | I45: =KANWIL!I45+SURABAYA!I45+KEDIRI!I45+MALANG!I45+MADIUN!I45+BANYUWANGI!I45 -> 8272461 | J45: =KANWIL!J45+SURABAYA!J45+KEDIRI!J45+MALANG!J45+MADIUN!J45+BANYUWANGI!J45 -> 36398899 | K45: =SUM(F45:J45) -> 364555398 | L45: =KANWIL!L45+SURABAYA!L45+KEDIRI!L45+MALANG!L45+MADIUN!L45+BANYUWANGI!L45 -> 1.784013e+08 | N45: =KANWIL!N45+SURABAYA!N45+KEDIRI!N45+MALANG!N45+MADIUN!N45+BANYUWANGI!N45 -> 1869203.5 | O45: =KANWIL!O45+SURABAYA!O45+KEDIRI!O45+MALANG!O45+MADIUN!O45+BANYUWANGI!O45 -> 3876255.7 | P45: =KANWIL!P45+SURABAYA!P45+KEDIRI!P45+MALANG!P45+MADIUN!P45+BANYUWANGI!P45 -> 72569909 | Q45: =N45+O45+P45 -> 78315368 | R45: =SUM(L45:P45) -> 256716667 | S45: =IF(K45=0,0,R45/K45) -> 0.7041911
A46: 112 | E46: Beban tunjangan jabatan | F46: =KANWIL!F46+SURABAYA!F46+KEDIRI!F46+MALANG!F46+MADIUN!F46+BANYUWANGI!F46 -> 4718703168 | G46: =KANWIL!G46+SURABAYA!G46+KEDIRI!G46+MALANG!G46+MADIUN!G46+BANYUWANGI!G46 -> 0 | H46: =KANWIL!H46+SURABAYA!H46+KEDIRI!H46+MALANG!H46+MADIUN!H46+BANYUWANGI!H46 -> 96759287 | I46: =KANWIL!I46+SURABAYA!I46+KEDIRI!I46+MALANG!I46+MADIUN!I46+BANYUWANGI!I46 -> 124531748 | J46: =KANWIL!J46+SURABAYA!J46+KEDIRI!J46+MALANG!J46+MADIUN!J46+BANYUWANGI!J46 -> 547940862 | K46: =SUM(F46:J46) -> 5487935065 | L46: =KANWIL!L46+SURABAYA!L46+KEDIRI!L46+MALANG!L46+MADIUN!L46+BANYUWANGI!L46 -> 2.3255393e+09 | N46: =KANWIL!N46+SURABAYA!N46+KEDIRI!N46+MALANG!N46+MADIUN!N46+BANYUWANGI!N46 -> 27118692 | O46: =KANWIL!O46+SURABAYA!O46+KEDIRI!O46+MALANG!O46+MADIUN!O46+BANYUWANGI!O46 -> 52577544 | P46: =KANWIL!P46+SURABAYA!P46+KEDIRI!P46+MALANG!P46+MADIUN!P46+BANYUWANGI!P46 -> 9.4212279e+08 | Q46: =N46+O46+P46 -> 1.021819e+09 | R46: =SUM(L46:P46) -> 3347358334 | S46: =IF(K46=0,0,R46/K46) -> 0.6099486
A47: 113 | E47: Beban tunjangan cuti besar | F47: =KANWIL!F47+SURABAYA!F47+KEDIRI!F47+MALANG!F47+MADIUN!F47+BANYUWANGI!F47 -> 109801507 | G47: =KANWIL!G47+SURABAYA!G47+KEDIRI!G47+MALANG!G47+MADIUN!G47+BANYUWANGI!G47 -> 0 | H47: =KANWIL!H47+SURABAYA!H47+KEDIRI!H47+MALANG!H47+MADIUN!H47+BANYUWANGI!H47 -> 2251533 | I47: =KANWIL!I47+SURABAYA!I47+KEDIRI!I47+MALANG!I47+MADIUN!I47+BANYUWANGI!I47 -> 2897782 | J47: =KANWIL!J47+SURABAYA!J47+KEDIRI!J47+MALANG!J47+MADIUN!J47+BANYUWANGI!J47 -> 12750269 | K47: =SUM(F47:J47) -> 127701091
...

Sheet KANWIL
D1: PT JAMKRINDO KANWIL SURABAYA
D2: LABA RUGI RKA TAHUN 2026
D5: URAIAN | F5: KANWIL SURABAYA | L5: REALISASI KANWIL SURABAYA | S5: %
F6: KUR | G6: PEN | H6: KBG/SURETYSHIP | I6: KONSUMTIF | J6: PRODUKTIF | K6: TOTAL | L6: KUR | M6: PEN | N6: KBG/SURETYSHIP | O6: KONSUMTIF | P6: PRODUKTIF | Q6: NON KUR | R6: TOTAL | S6: %
F7: (a) | G7: (b) | H7: (c) | I7: (d) | J7: (e) | K7: (f) | L7: (g) | M7: (h) | N7: (i) | O7: (j) | P7: (k) | Q7: (l)=i+j+k | R7: (m) | S7: (n)=m/f
C9: X1 | D9: VOLUME | F9: 0 | G9: 0 | H9: 0 | I9: 0 | J9: 0 | K9: 0
C11: X2 | D11: PENDAPATAN PENJAMINAN
A12: 7 | B12: 8 | E12: Imbal Jasa Penjaminan Bruto | F12: 0 | G12: 0 | H12: 0 | I12: 0 | J12: 0 | K12: 0
A13: 12 | B13: 10 | E13: Restitusi penjaminan kredit | F13: 0 | G13: 0 | H13: 0 | I13: 0 | J13: 0 | K13: 0
A14: 9 | B14: 9 | E14: Premi Penjaminan Ulang | F14: 0 | G14: 0 | H14: 0 | I14: 0 | J14: 0 | K14: 0
C15: Y2 | E15: IMBAL JASA PENJAMINAN BERSIH | F15: 0 | G15: 0 | H15: 0 | I15: 0 | J15: 0 | K15: 0
C16: 22
C17: X2 | D17: BEBAN KLAIM
A18: 22 | B18: 13 | E18: Beban Klaim | F18: 0 | G18: 0 | H18: 0 | I18: 0 | J18: 0 | K18: 0
A19: 24 | B19: 14 | E19: Kenaikan (Penurunan) Cadangan Klaim | F19: 0 | G19: 0 | H19: 0 | I19: 0 | J19: 0 | K19: 0
A20: 32 | B20: 15 | E20: Pendapatan Subrogasi | F20: 0 | G20: 0 | H20: 0 | I20: 0 | J20: 0 | K20: 0
A21: 37 | B21: 16 | E21: Beban Komisi Netto | F21: 0 | G21: 0 | H21: 0 | I21: 0 | J21: 0 | K21: 0
C22: Y2 | E22: JUMLAH BEBAN KLAIM | F22: 0 | G22: 0 | H22: 0 | I22: 0 | J22: 0 | K22: 0
C24: X1 | D24: PENJAMINAN BERSIH | F24: 0 | G24: 0 | H24: 0 | I24: 0 | J24: 0 | K24: 0
B26: 19 | C26: X1 | D26: PENDAPATAN INVESTASI BERSIH | F26: 0 | G26: 0 | H26: 0 | I26: 0 | J26: 0 | K26: 0
C28: X1 | D28: BEBAN USAHA
C29: X2 | E29: BEBAN KARYAWAN
A30: 94 | E30: Beban gaji karyawan | F30: 1696793732 | G30: 0 | H30: 34793575 | I30: 44780247 | J30: 197033505 | K30: =SUM(F30:J30) -> 1973401059 | L30: 7.7489527e+08 | N30: 9298167.8 | O30: 16510706 | P30: 3.1456129e+08 | Q30: =N30+O30+P30 -> 3.4037017e+08 | R30: =SUM(L30:P30) -> 1.1152654e+09 | S30: =IF(K30=0,0,R30/K30) -> 0.5651489
A31: 95 | E31: Beban lembur karyawan | F31: 43007556 | G31: 0 | H31: 881891 | I31: 1135017 | J31: 4994083 | K31: =SUM(F31:J31) -> 50018547 | L31: 16581527 | N31: 168906.41 | O31: 299926.21 | P31: 5714181.7 | Q31: =N31+O31+P31 -> 6183014.3 | R31: =SUM(L31:P31) -> 22764541 | S31: =IF(K31=0,0,R31/K31) -> 0.455122
A32: 96 | E32: Beban asuransi kesehatan karyawan | F32: 180463354 | G32: 0 | H32: 3700488 | I32: 4762626 | J32: 20955598 | K32: =SUM(F32:J32) -> 209882066 | L32: 6418318.8 | N32: 76235.301 | O32: 135370.61 | P32: 2579075.3 | Q32: =N32+O32+P32 -> 2790681.2 | R32: =SUM(L32:P32) -> 9209000 | S32: =IF(K32=0,0,R32/K32) -> 0.043877022
A33: 97 | E33: Beban asuransi jiwa karyawan | F33: 8268054 | G33: 0 | H33: 169540 | I33: 218203 | J33: 960095 | K33: =SUM(F33:J33) -> 9615892
A34: 100 | E34: Beban dana pensiun | F34: 131045331 | G34: 0 | H34: 2687148 | I34: 3458430 | J34: 15217124 | K34: =SUM(F34:J34) -> 152408033
A35: 101 | E35: Beban kompensasi kinerja karyawan | F35: 2154273121 | G35: 0 | H35: 44174411 | I35: 56853630 | J35: 250156501 | K35: =SUM(F35:J35) -> 2505457663 | L35: 9.9943875e+08 | N35: 11989437 | O35: 21289578 | P35: 4.0560816e+08 | Q35: =N35+O35+P35 -> 4.3888718e+08 | R35: =SUM(L35:P35) -> 1.4383259e+09 | S35: =IF(K35=0,0,R35/K35) -> 0.57407712
A36: 102 | E36: Biaya jasa kini karyawan | F36: 0 | G36: 0 | H36: 0 | I36: 0 | J36: 0 | K36: =SUM(F36:J36) -> 0
A37: 103 | E37: Biaya jasa lalu karyawan | F37: 0 | G37: 0 | H37: 0 | I37: 0 | J37: 0 | K37: =SUM(F37:J37) -> 0
A38: 104 | E38: Bunga atas imbalan pasca kerja karyawan | F38: 198153866 | G38: 0 | H38: 4063241 | I38: 5229498 | J38: 23009839 | K38: =SUM(F38:J38) -> 230456444
A39: 105 | E39: Beban BPJS kesehatan karyawan | F39: 50291539 | G39: 0 | H39: 1031252 | I39: 1327249 | J39: 5839908 | K39: =SUM(F39:J39) -> 58489948
A40: 106 | E40: Beban BPJS jaminan hari tua karyawan | F40: 71343529 | G40: 0 | H40: 1462934 | I40: 1882834 | J40: 8284487 | K40: =SUM(F40:J40) -> 82973784
A41: 107 | E41: Beban BPJS jaminan kecelakaan kerja dan jaminan kematian karyawan | F41: 10354282 | G41: 0 | H41: 212320 | I41: 273261 | J41: 1202350 | K41: =SUM(F41:J41) -> 12042213
A42: 108 | E42: Beban BPJS jaminan pensiun karyawan | F42: 23991631 | G42: 0 | H42: 491960 | I42: 633165 | J42: 2785934 | K42: =SUM(F42:J42) -> 27902690
A43: 109 | E43: Beban tunjangan hari raya karyawan | F43: 401073878 | G43: 0 | H43: 8224214 | I43: 10584779 | J43: 46573128 | K43: =SUM(F43:J43) -> 466455999 | L43: 3.018787e+08 | N43: 3771792.7 | O43: 6697551.9 | P43: 1.2760148e+08 | Q43: =N43+O43+P43 -> 1.3807083e+08 | R43: =SUM(L43:P43) -> 4.3994953e+08 | S43: =IF(K43=0,0,R43/K43) -> 0.94317477
A44: 110 | E44: Beban tunjangan PPh 21 karyawan | F44: 976585 | G44: 0 | H44: 20025 | I44: 25773 | J44: 113402 | K44: =SUM(F44:J44) -> 1135785
A45: 111 | E45: Beban tunjangan transportasi karyawan | F45: 102363826 | G45: 0 | H45: 2099020 | I45: 2701494 | J45: 11886597 | K45: =SUM(F45:J45) -> 119050937 | L45: 33038265 | N45: 396428.83 | O45: 703936.53 | P45: 13411370 | Q45: =N45+O45+P45 -> 14511735 | R45: =SUM(L45:P45) -> 47550000 | S45: =IF(K45=0,0,R45/K45) -> 0.39940887
A46: 112 | E46: Beban tunjangan jabatan | F46: 990927668 | G46: 0 | H46: 20319450 | I46: 26151667 | J46: 115067581 | K46: =SUM(F46:J46) -> 1152466366 | L46: 4.9016795e+08 | N46: 5883310.8 | O46: 10446963 | P46: 1.9903511e+08 | Q46: =N46+O46+P46 -> 2.1536538e+08 | R46: =SUM(L46:P46) -> 705533333 | S46: =IF(K46=0,0,R46/K46) -> 0.61219429
A47: 113 | E47: Beban tunjangan cuti besar | F47: 16470226 | G47: 0 | H47: 337730 | I47: 434667 | J47: 1912540 | K47: =SUM(F47:J47) -> 19155163
...

Sheet SURABAYA
D1: PT JAMKRINDO KANWIL SURABAYA
D2: LABA RUGI RKA TAHUN 2026
D5: URAIAN | F5: KANCA SURABAYA | L5: REALISASI KANCA SURABAYA | S5: %
F6: KUR | G6: PEN | H6: KBG/SURETYSHIP | I6: KONSUMTIF | J6: PRODUKTIF | K6: TOTAL | L6: KUR | M6: PEN | N6: KBG/SURETYSHIP | O6: KONSUMTIF | P6: PRODUKTIF | Q6: NON KUR | R6: TOTAL | S6: %
F7: (a) | G7: (b) | H7: (c) | I7: (d) | J7: (e) | K7: (f) | L7: (g) | M7: (h) | N7: (i) | O7: (j) | P7: (k) | Q7: (l)=i+j+k | R7: (m) | S7: (n)=m/f
C9: X1 | D9: VOLUME | F9: 9912949637720 | G9: 0 | H9: 3913532224491 | I9: 974545539188 | J9: 2361265957530 | K9: =SUM(F9:J9) -> 17162293358929
C11: X2 | D11: PENDAPATAN PENJAMINAN
A12: 7 | B12: 8 | E12: Imbal Jasa Penjaminan Bruto | F12: 358429774172 | G12: 0 | H12: 12754022487 | I12: 9459354711 | J12: 42658164985 | K12: =SUM(F12:J12) -> 423301316355 | L12: 1.9051406e+11 | N12: 4.5279697e+09 | O12: 4.2004547e+09 | P12: 6.5806041e+10 | Q12: =N12+O12+P12 -> 7.4534465e+10 | R12: =SUM(L12:P12) -> 2.6504852e+11 | S12: =IF(K12=0,0,R12/K12) -> 0.62614623
A13: 12 | B13: 10 | E13: Restitusi penjaminan kredit | F13: 0 | G13: 0 | H13: 0 | I13: 0 | J13: 0 | K13: =SUM(F13:J13) -> 0
A14: 9 | B14: 9 | E14: Premi Penjaminan Ulang | F14: 32275195681 | G14: 0 | H14: 1548572196 | I14: 1411596254 | J14: 24666604293 | K14: =SUM(F14:J14) -> 59901968424 | L14: 2.055736e+10 | N14: 4.5044739e+08 | O14: 5.8206944e+08 | P14: 8.8230974e+09 | Q14: =N14+O14+P14 -> 9.8556143e+09 | R14: =SUM(L14:P14) -> 3.0412974e+10 | S14: =IF(K14=0,0,R14/K14) -> 0.50771244
C15: Y2 | E15: IMBAL JASA PENJAMINAN BERSIH | F15: =F12-F13-F14 -> 326154578491 | G15: =G12-G13-G14 -> 0 | H15: =H12-H13-H14 -> 11205450291 | I15: =I12-I13-I14 -> 8047758457 | J15: =J12-J13-J14 -> 17991560692 | K15: =K12-K13-K14 -> 363399347931 | L15: =L12-L13-L14 -> 1.699567e+11 | N15: =N12-N13-N14 -> 4.0775223e+09 | O15: =O12-O13-O14 -> 3.6183853e+09 | P15: =P12-P13-P14 -> 5.6982943e+10 | Q15: =Q12-Q13-Q14 -> 6.4678851e+10 | R15: =R12-R13-R14 -> 2.3463555e+11 | S15: =IF(K15=0,0,R15/K15) -> 0.6456686
C16: 22
C17: X2 | D17: BEBAN KLAIM
A18: 22 | B18: 13 | E18: Beban Klaim | F18: 279117753977 | G18: 22334975222 | H18: 5202817631 | I18: 5124694714 | J18: 37261618379 | K18: =SUM(F18:J18) -> 349041859923 | L18: 1.3797285e+11 | M18: 4359222990 | N18: 2175356536 | O18: 1.3886522e+08 | P18: 6.0839283e+10 | Q18: =N18+O18+P18 -> 6.3153505e+10 | R18: =SUM(L18:P18) -> 2.0548558e+11 | S18: =IF(K18=0,0,R18/K18) -> 0.58871328
A19: 24 | B19: 14 | E19: Kenaikan (Penurunan) Cadangan Klaim | F19: 1747285621 | G19: -5867662416 | H19: 17700890 | I19: 264667074 | J19: 8523487423 | K19: =SUM(F19:J19) -> 4685478592 | L19: 1.9340688e+10 | M19: -5.8676624e+09 | N19: 0 | O19: 0 | P19: 0 | Q19: 5.2168328e+09 | R19: =SUM(L19:Q19) -> 1.8689859e+10 | S19: =IF(K19=0,0,R19/K19) -> 3.98889
A20: 32 | B20: 15 | E20: Pendapatan Subrogasi | F20: 71739819407 | G20: 17075082318 | H20: 59056287 | I20: 120506747 | J20: 26509953142 | K20: =SUM(F20:J20) -> 115504417901 | L20: 5.3678578e+10 | M20: 7.6528895e+09 | O20: 25480715 | P20: 1.985216e+10 | Q20: 1.7958707e+10 | R20: 7.9290175e+10 | S20: =IF(K20=0,0,R20/K20) -> 0.68646876
A21: 37 | B21: 16 | E21: Beban Komisi Netto | F21: 5093038920 | G21: 0 | H21: 269126234 | I21: 215756309 | J21: 3766766262 | K21: =SUM(F21:J21) -> 9344687725 | L21: 3.3672537e+09 | N21: 69094281 | O21: -31054658 | P21: 1.2335438e+09 | Q21: =N21+O21+P21 -> 1.2715834e+09 | R21: =SUM(L21:P21) -> 4.6388371e+09 | S21: =IF(K21=0,0,R21/K21) -> 0.49641435
C22: Y2 | E22: JUMLAH BEBAN KLAIM | F22: =F18+F19-F20-F21 -> 204032181271 | G22: =G18+G19-G20-G21 -> -607769512 | H22: =H18+H19-H20-H21 -> 4892336000 | I22: =I18+I19-I20-I21 -> 5053098732 | J22: =J18+J19-J20-J21 -> 15508386398 | K22: =K18+K19-K20-K21 -> 228878232889 | L22: =L18+L19-L20-L21 -> 1.0026771e+11 | M22: =M18+M19-M20-M21 -> -9.1613289e+09 | ... R22: =R18+R19-R20-R21 -> 1.4024643e+11 | S22: =IF(K22=0,0,R22/K22) -> 0.61275563
C24: X1 | D24: PENJAMINAN BERSIH | F24: =F15-F22 -> 122122397220 | G24: =G15-G22 -> 607769512 | H24: =H15-H22 -> 6313114291 | I24: =I15-I22 -> 2994659725 | J24: =J15-J22 -> 2483174294 | K24: =K15-K22 -> 134521115042 | L24: =L15-L22 -> 6.9688992e+10 | M24: =M15-M22 -> 9.1613289e+09 | ... R24: =R15-R22 -> 9.4389124e+10 | S24: =IF(K24=0,0,R24/K24) -> 0.70166772
B26: 19 | C26: X1 | D26: PENDAPATAN INVESTASI BERSIH | F26: 0 | G26: 0 | H26: 0 | I26: 0 | J26: 0 | K26: 0
C28: X1 | D28: BEBAN USAHA
C29: X2 | E29: BEBAN KARYAWAN
A30: 94 | E30: Beban gaji karyawan | F30: 2019992538 | G30: 0 | H30: 41420923 | I30: 53309818 | J30: 234563696 | K30: =SUM(F30:J30) -> 2349286975 | L30: 1.0430392e+09 | N30: 27819101 | O30: 25806903 | P30: 4.0430149e+08 | Q30: =N30+O30+P30 -> 4.5792749e+08 | R30: =SUM(L30:P30) -> 1500966714 | S30: =IF(K30=0,0,R30/K30) -> 0.63890309
A31: 95 | E31: Beban lembur karyawan | F31: 80955400 | G31: 0 | H31: 1660030 | I31: 2136502 | J31: 9400628 | K31: =SUM(F31:J31) -> 94152560 | L31: 40590423 | N31: 1067323.6 | O31: 990122.44 | P31: 15511663 | Q31: =N31+O31+P31 -> 17569109 | R31: =SUM(L31:P31) -> 58159532 | S31: =IF(K31=0,0,R31/K31) -> 0.61771589
A32: 96 | E32: Beban asuransi kesehatan karyawan | F32: 360926704 | G32: 0 | H32: 7400976 | I32: 9525251 | J32: 41911195 | K32: =SUM(F32:J32) -> 419764126
A33: 97 | E33: Beban asuransi jiwa karyawan | F33: 16536107 | G33: 0 | H33: 339081 | I33: 436406 | J33: 1920190 | K33: =SUM(F33:J33) -> 19231784
A34: 100 | E34: Beban dana pensiun | F34: 262090662 | G34: 0 | H34: 5374296 | I34: 6916860 | J34: 30434248 | K34: =SUM(F34:J34) -> 304816066
A35: 101 | E35: Beban kompensasi kinerja karyawan | F35: 2639551770 | G35: 0 | H35: 54125284 | I35: 69660665 | J35: 306507577 | K35: =SUM(F35:J35) -> 3069845296 | L35: 1.4262024e+09 | N35: 38047335 | O35: 35295313 | P35: 5.529508e+08 | Q35: =N35+O35+P35 -> 6.2629345e+08 | R35: =SUM(L35:P35) -> 2.0524958e+09 | S35: =IF(K35=0,0,R35/K35) -> 0.66859911
A36: 102 | E36: Biaya jasa kini karyawan | F36: 0 | G36: 0 | H36: 0 | I36: 0 | J36: 0 | K36: =SUM(F36:J36) -> 0
A37: 103 | E37: Biaya jasa lalu karyawan | F37: 0 | G37: 0 | H37: 0 | I37: 0 | J37: 0 | K37: =SUM(F37:J37) -> 0
A38: 104 | E38: Bunga atas imbalan pasca kerja karyawan | F38: 396307733 | G38: 0 | H38: 8126482 | I38: 10458996 | J38: 46019678 | K38: =SUM(F38:J38) -> 460912889
A39: 105 | E39: Beban BPJS kesehatan karyawan | F39: 100583081 | G39: 0 | H39: 2062505 | I39: 2654498 | J39: 11679815 | K39: =SUM(F39:J39) -> 116979899
A40: 106 | E40: Beban BPJS jaminan hari tua karyawan | F40: 142687058 | G40: 0 | H40: 2925867 | I40: 3765668 | J40: 16568974 | K40: =SUM(F40:J40) -> 165947567
A41: 107 | E41: Beban BPJS jaminan kecelakaan kerja dan jaminan kematian karyawan | F41: 20708564 | G41: 0 | H41: 424639 | I41: 546522 | J41: 2404701 | K41: =SUM(F41:J41) -> 24084426
A42: 108 | E42: Beban BPJS jaminan pensiun karyawan | F42: 47983259 | G42: 0 | H42: 983920 | I42: 1266331 | J42: 5571867 | K42: =SUM(F42:J42) -> 55805377
A43: 109 | E43: Beban tunjangan hari raya karyawan | F43: 695650945 | G43: 0 | H43: 14264659 | I43: 18358991 | J43: 80779732 | K43: =SUM(F43:J43) -> 809054327 | L43: 4.307819e+08 | N43: 11969425 | O43: 11103658 | P43: 1.7395444e+08 | Q43: =N43+O43+P43 -> 1.9702752e+08 | R43: =SUM(L43:P43) -> 6.2780943e+08 | S43: =IF(K43=0,0,R43/K43) -> 0.77597932
A44: 110 | E44: Beban tunjangan PPh 21 karyawan | F44: 1603647260 | G44: 0 | H44: 32883562 | I44: 42322009 | J44: 186217237 | K44: =SUM(F44:J44) -> 1865070068 | L44: 2.489024e+08 | N44: 7177989.4 | O44: 6658794.5 | P44: 1.043194e+08 | Q44: =N44+O44+P44 -> 1.1815618e+08 | R44: =SUM(L44:P44) -> 3.6705858e+08 | S44: =IF(K44=0,0,R44/K44) -> 0.19680686
A45: 111 | E45: Beban tunjangan transportasi karyawan | F45: 83963494 | G45: 0 | H45: 1721712 | I45: 2215889 | J45: 9749931 | K45: =SUM(F45:J45) -> 97651026 | L45: 38538807 | N45: 1028367.7 | O45: 953984.31 | P45: 14945508 | Q45: =N45+O45+P45 -> 16927860 | R45: =SUM(L45:P45) -> 55466667 | S45: =IF(K45=0,0,R45/K45) -> 0.56800906
A46: 112 | E46: Beban tunjangan jabatan | F46: 943740633 | G46: 0 | H46: 19351858 | I46: 24906350 | J46: 109588173 | K46: =SUM(F46:J46) -> 1097587014 | L46: 5.9729626e+08 | N46: 15947612 | O46: 14794097 | P46: 2.3177037e+08 | Q46: =N46+O46+P46 -> 2.6251207e+08 | R46: =SUM(L46:P46) -> 859808334 | S46: =IF(K46=0,0,R46/K46) -> 0.78336234
A47: 113 | E47: Beban tunjangan cuti besar | F47: 32940452 | G47: 0 | H47: 675460 | I47: 869335 | J47: 3825081 | K47: =SUM(F47:J47) -> 38310328
...

Sheet KEDIRI
D1: PT JAMKRINDO KANWIL SURABAYA
D2: LABA RUGI RKA TAHUN 2026
D5: URAIAN | F5: KANCA KEDIRI | L5: REALISASI KANCA KEDIRI | S5: %
F6: KUR | G6: PEN | H6: KBG/SURETYSHIP | I6: KONSUMTIF | J6: PRODUKTIF | K6: TOTAL | L6: KUR | M6: PEN | N6: KBG/SURETYSHIP | O6: KONSUMTIF | P6: PRODUKTIF | Q6: NON KUR | R6: TOTAL | S6: %
F7: (a) | G7: (b) | H7: (c) | I7: (d) | J7: (e) | K7: (f) | L7: (g) | M7: (h) | N7: (i) | O7: (j) | P7: (k) | Q7: (l)=i+j+k | R7: (m) | S7: (n)=m/f
C9: X1 | D9: VOLUME | F9: 5539589503431 | G9: 0 | H9: 729641601176 | I9: 544598977781 | J9: 1004253035090 | K9: =SUM(F9:J9) -> 7818083117478
C11: X2 | D11: PENDAPATAN PENJAMINAN
A12: 7 | B12: 8 | E12: Imbal Jasa Penjaminan Bruto | F12: 200298991450 | G12: 0 | H12: 2377868599 | I12: 5286109986 | J12: 22927120245 | K12: =SUM(F12:J12) -> 230890090280 | L12: 1.0346593e+11 | N12: 1.7436172e+08 | O12: 1.7123644e+09 | P12: 3.9655769e+10 | Q12: =N12+O12+P12 -> 4.1542495e+10 | R12: =SUM(L12:P12) -> 1.4500842e+11 | S12: =IF(K12=0,0,R12/K12) -> 0.62804091
A13: 12 | B13: 10 | E13: Restitusi penjaminan kredit | F13: 0 | G13: 0 | H13: 0 | I13: 0 | J13: 0 | K13: =SUM(F13:J13) -> 0
A14: 9 | B14: 9 | E14: Premi Penjaminan Ulang | F14: 18036138761 | G14: 0 | H14: 288716850 | I14: 788833201 | J14: 13671394317 | K14: =SUM(F14:J14) -> 32785083129 | L14: 1.0807965e+10 | N14: 24792021 | O14: 1.4708132e+08 | P14: 5.1338238e+09 | Q14: =N14+O14+P14 -> 5.3056972e+09 | R14: =SUM(L14:P14) -> 16113662010 | S14: =IF(K14=0,0,R14/K14) -> 0.49149371
C15: Y2 | E15: IMBAL JASA PENJAMINAN BERSIH | F15: =F12-F13-F14 -> 182262852689 | G15: =G12-G13-G14 -> 0 | H15: =H12-H13-H14 -> 2089151749 | I15: =I12-I13-I14 -> 4497276785 | J15: =J12-J13-J14 -> 9255725928 | K15: =K12-K13-K14 -> 198105007151 | L15: =L12-L13-L14 -> 9.2657962e+10 | N15: =N12-N13-N14 -> 1.495697e+08 | O15: =O12-O13-O14 -> 1.565283e+09 | P15: =P12-P13-P14 -> 3.4521945e+10 | Q15: =Q12-Q13-Q14 -> 3.6236798e+10 | R15: =R12-R13-R14 -> 1.2889476e+11 | S15: =IF(K15=0,0,R15/K15) -> 0.65063858
C16: 22
C17: X2 | D17: BEBAN KLAIM
A18: 22 | B18: 13 | E18: Beban Klaim | F18: 149669107251 | G18: 1889067548 | H18: 158460622 | I18: 500000000 | J18: 25924281317 | K18: =SUM(F18:J18) -> 178140916738 | L18: 5.7450231e+10 | M18: 116546366 | O18: 116203474 | P18: 2.5283506e+10 | Q18: =N18+O18+P18 -> 2.5399709e+10 | R18: =SUM(L18:P18) -> 8.2966487e+10 | S18: =IF(K18=0,0,R18/K18) -> 0.46573515
A19: 24 | B19: 14 | E19: Kenaikan (Penurunan) Cadangan Klaim | F19: 1219679297 | G19: -151546366 | H19: 17700891 | I19: 0 | J19: 3523812717 | K19: =SUM(F19:J19) -> 4609646539 | L19: 8.0102758e+09 | M19: -1.5154637e+08 | N19: 0 | O19: 0 | P19: 0 | Q19: 9.2901233e+09 | R19: =SUM(L19:Q19) -> 1.7148853e+10 | S19: =IF(K19=0,0,R19/K19) -> 3.7202099
A20: 32 | B20: 15 | E20: Pendapatan Subrogasi | F20: 43057773776 | G20: 4180457975 | H20: 30365867 | I20: 61962783 | J20: 19772876680 | K20: =SUM(F20:J20) -> 67103437081 | L20: 1.4900423e+10 | M20: 9.184166e+08 | O20: 22887366 | P20: 9.5023675e+09 | Q20: 8.3941876e+09 | R20: 2.4213027e+10 | S20: =IF(K20=0,0,R20/K20) -> 0.3608314
A21: 37 | B21: 16 | E21: Beban Komisi Netto | F21: 2846109985 | G21: 0 | H21: 50176077 | I21: 120569702 | J21: 2085992135 | K21: =SUM(F21:J21) -> 5102847899 | L21: 1.7865182e+09 | N21: 3704017 | O21: 4871413 | P21: 7.5442253e+08 | Q21: =N21+O21+P21 -> 7.6299796e+08 | R21: =SUM(L21:P21) -> 2.5495161e+09 | S21: =IF(K21=0,0,R21/K21) -> 0.49962612
C22: Y2 | E22: JUMLAH BEBAN KLAIM | F22: =F18+F19-F20-F21 -> 104984902787 | G22: =G18+G19-G20-G21 -> -2442936793 | H22: =H18+H19-H20-H21 -> 95619569 | I22: =I18+I19-I20-I21 -> 317467515 | J22: =J18+J19-J20-J21 -> 7589225219 | K22: =K18+K19-K20-K21 -> 110544278297 | L22: =L18+L19-L20-L21 -> 4.8773566e+10 | M22: =M18+M19-M20-M21 -> -953416597 | ... R22: =R18+R19-R20-R21 -> 7.3352796e+10 | S22: =IF(K22=0,0,R22/K22) -> 0.66356031
C24: X1 | D24: PENJAMINAN BERSIH | F24: =F15-F22 -> 77277949902 | G24: =G15-G22 -> 2442936793 | H24: =H15-H22 -> 1993532180 | I24: =I15-I22 -> 4179809270 | J24: =J15-J22 -> 1666500709 | K24: =K15-K22 -> 87560728854 | L24: =L15-L22 -> 4.3884396e+10 | M24: =M15-M22 -> 953416597 | ... R24: =R15-R22 -> 5.5541963e+10 | S24: =IF(K24=0,0,R24/K24) -> 0.63432505
B26: 19 | C26: X1 | D26: PENDAPATAN INVESTASI BERSIH | F26: 0 | G26: 0 | H26: 0 | I26: 0 | J26: 0 | K26: 0
C28: X1 | D28: BEBAN USAHA
C29: X2 | E29: BEBAN KARYAWAN
A30: 94 | E30: Beban gaji karyawan | F30: 969596418 | G30: 0 | H30: 19882043 | I30: 25588713 | J30: 112590574 | K30: =SUM(F30:J30) -> 1127657748 | L30: 5.1681078e+08 | N30: 952514.54 | O30: 9354415.3 | P30: 2.1663411e+08 | Q30: =N30+O30+P30 -> 2.2694104e+08 | R30: =SUM(L30:P30) -> 743751821 | S30: =IF(K30=0,0,R30/K30) -> 0.65955457
A31: 95 | E31: Beban lembur karyawan | F31: 35417988 | G31: 0 | H31: 726263 | I31: 934720 | J31: 4112775 | K31: =SUM(F31:J31) -> 41191746 | L31: 13555184 | N31: 25541.937 | O31: 250841.2 | P31: 5809102.8 | Q31: =N31+O31+P31 -> 6085486 | R31: =SUM(L31:P31) -> 19640670 | S31: =IF(K31=0,0,R31/K31) -> 0.47681082
A32: 96 | E32: Beban asuransi kesehatan karyawan | F32: 180463352 | G32: 0 | H32: 3700488 | I32: 4762626 | J32: 20955598 | K32: =SUM(F32:J32) -> 209882064 | L32: 7643750 | N32: 11988.222 | O32: 117733.44 | P32: 2726528.3 | Q32: =N32+O32+P32 -> 2856250 | R32: =SUM(L32:P32) -> 10500000 | S32: =IF(K32=0,0,R32/K32) -> 0.050028096
A33: 97 | E33: Beban asuransi jiwa karyawan | F33: 8268054 | G33: 0 | H33: 169540 | I33: 218203 | J33: 960095 | K33: =SUM(F33:J33) -> 9615892
A34: 100 | E34: Beban dana pensiun | F34: 131045331 | G34: 0 | H34: 2687148 | I34: 3458430 | J34: 15217124 | K34: =SUM(F34:J34) -> 152408033
A35: 101 | E35: Beban kompensasi kinerja karyawan | F35: 1395994313 | G35: 0 | H35: 28625538 | I35: 36841820 | J35: 162104354 | K35: =SUM(F35:J35) -> 1623566025 | L35: 6.7312524e+08 | N35: 1240655.3 | O35: 12184177 | P35: 2.8216711e+08 | Q35: =N35+O35+P35 -> 2.9559194e+08 | R35: =SUM(L35:P35) -> 9.6871718e+08 | S35: =IF(K35=0,0,R35/K35) -> 0.59666017
A36: 102 | E36: Biaya jasa kini karyawan | F36: 0 | G36: 0 | H36: 0 | I36: 0 | J36: 0 | K36: =SUM(F36:J36) -> 0
A37: 103 | E37: Biaya jasa lalu karyawan | F37: 0 | G37: 0 | H37: 0 | I37: 0 | J37: 0 | K37: =SUM(F37:J37) -> 0
A38: 104 | E38: Bunga atas imbalan pasca kerja karyawan | F38: 198153866 | G38: 0 | H38: 4063241 | I38: 5229498 | J38: 23009839 | K38: =SUM(F38:J38) -> 230456444
A39: 105 | E39: Beban BPJS kesehatan karyawan | F39: 50291541 | G39: 0 | H39: 1031252 | I39: 1327249 | J39: 5839908 | K39: =SUM(F39:J39) -> 58489950
A40: 106 | E40: Beban BPJS jaminan hari tua karyawan | F40: 71343529 | G40: 0 | H40: 1462934 | I40: 1882834 | J40: 8284487 | K40: =SUM(F40:J40) -> 82973784
A41: 107 | E41: Beban BPJS jaminan kecelakaan kerja dan jaminan kematian karyawan | F41: 10354282 | G41: 0 | H41: 212320 | I41: 273261 | J41: 1202350 | K41: =SUM(F41:J41) -> 12042213
A42: 108 | E42: Beban BPJS jaminan pensiun karyawan | F42: 23991629 | G42: 0 | H42: 491960 | I42: 633165 | J42: 2785934 | K42: =SUM(F42:J42) -> 27902688
A43: 109 | E43: Beban tunjangan hari raya karyawan | F43: 290834566 | G43: 0 | H43: 5963703 | I43: 7675443 | J43: 33772021 | K43: =SUM(F43:J43) -> 338245733 | L43: 2.0331628e+08 | N43: 390301.47 | O43: 3833056.5 | P43: 88767792 | Q43: =N43+O43+P43 -> 92991150 | R43: =SUM(L43:P43) -> 2.9630743e+08 | S43: =IF(K43=0,0,R43/K43) -> 0.87601233
A44: 110 | E44: Beban tunjangan PPh 21 karyawan | F44: 1123262216 | G44: 0 | H44: 23033034 | I44: 29644121 | J44: 130434411 | K44: =SUM(F44:J44) -> 1306373782 | L44: 1.5129303e+08 | N44: 289626.99 | O44: 2844356.8 | P44: 65871002 | Q44: =N44+O44+P44 -> 69004985 | R44: =SUM(L44:P44) -> 2.2029802e+08 | S44: =IF(K44=0,0,R44/K44) -> 0.16863322
A45: 111 | E45: Beban tunjangan transportasi karyawan | F45: 34442168 | G45: 0 | H45: 706253 | I45: 908967 | J45: 3999461 | K45: =SUM(F45:J45) -> 40056849 | L45: 25635000 | N45: 47001.525 | O45: 461590.63 | P45: 10689741 | Q45: =N45+O45+P45 -> 11198333 | R45: =SUM(L45:P45) -> 36833333 | S45: =IF(K45=0,0,R45/K45) -> 0.91952647
A46: 112 | E46: Beban tunjangan jabatan | F46: 707805475 | G46: 0 | H46: 14513893 | I46: 18679762 | J46: 82191129 | K46: =SUM(F46:J46) -> 823190259 | L46: 3.1628472e+08 | N46: 583613.35 | O46: 5731525.8 | P46: 1.3273347e+08 | Q46: =N46+O46+P46 -> 1.3904861e+08 | R46: =SUM(L46:P46) -> 4.5533333e+08 | S46: =IF(K46=0,0,R46/K46) -> 0.55313256
A47: 113 | E47: Beban tunjangan cuti besar | F47: 16470226 | G47: 0 | H47: 337730 | I47: 434667 | J47: 1912540 | K47: =SUM(F47:J47) -> 19155163
...

Sheet MALANG
D1: PT JAMKRINDO KANWIL SURABAYA
D2: LABA RUGI RKA TAHUN 2026
D5: URAIAN | F5: KANCA MALANG | L5: REALISASI KANCA MALANG | S5: %
F6: KUR | G6: PEN | H6: KBG/SURETYSHIP | I6: KONSUMTIF | J6: PRODUKTIF | K6: TOTAL | L6: KUR | M6: PEN | N6: KBG/SURETYSHIP | O6: KONSUMTIF | P6: PRODUKTIF | Q6: NON KUR | R6: TOTAL | S6: %
F7: (a) | G7: (b) | H7: (c) | I7: (d) | J7: (e) | K7: (f) | L7: (g) | M7: (h) | N7: (i) | O7: (j) | P7: (k) | Q7: (l)=i+j+k | R7: (m) | S7: (n)=m/f
C9: X1 | D9: VOLUME | F9: 4664917476573 | G9: 0 | H9: 795972655829 | I9: 458609665500 | J9: 884960450602 | K9: =SUM(F9:J9) -> 6804460248504
C11: X2 | D11: PENDAPATAN PENJAMINAN
A12: 7 | B12: 8 | E12: Imbal Jasa Penjaminan Bruto | F12: 168672834905 | G12: 0 | H12: 2594038472 | I12: 4451461041 | J12: 19420563629 | K12: =SUM(F12:J12) -> 195138898047 | L12: 8.6405665e+10 | N12: 2.2767948e+08 | O12: 7.006785e+08 | P12: 2.7476169e+10 | Q12: =N12+O12+P12 -> 2.8404527e+10 | R12: =SUM(L12:P12) -> 1.1481019e+11 | S12: =IF(K12=0,0,R12/K12) -> 0.58835113
A13: 12 | B13: 10 | E13: Restitusi penjaminan kredit | F13: 0 | G13: 0 | H13: 0 | I13: 0 | J13: 0 | K13: =SUM(F13:J13) -> 0
A14: 9 | B14: 9 | E14: Premi Penjaminan Ulang | F14: 15188327378 | G14: 0 | H14: 314963836 | I14: 664280590 | J14: 11526814963 | K14: =SUM(F14:J14) -> 27694386767 | L14: 9.3492692e+09 | N14: 20674430 | O14: 74595908 | P14: 3.4059489e+09 | Q14: =N14+O14+P14 -> 3.5012192e+09 | R14: =SUM(L14:P14) -> 1.2850488e+10 | S14: =IF(K14=0,0,R14/K14) -> 0.46401058
C15: Y2 | E15: IMBAL JASA PENJAMINAN BERSIH | F15: =F12-F13-F14 -> 153484507527 | G15: =G12-G13-G14 -> 0 | H15: =H12-H13-H14 -> 2279074636 | I15: =I12-I13-I14 -> 3787180451 | J15: =J12-J13-J14 -> 7893748666 | K15: =K12-K13-K14 -> 167444511280 | L15: =L12-L13-L14 -> 7.7056396e+10 | N15: =N12-N13-N14 -> 2.0700505e+08 | O15: =O12-O13-O14 -> 6.2608259e+08 | P15: =P12-P13-P14 -> 2.407022e+10 | Q15: =Q12-Q13-Q14 -> 2.4903307e+10 | R15: =R12-R13-R14 -> 1.019597e+11 | S15: =IF(K15=0,0,R15/K15) -> 0.60891637
C16: 22
C17: X2 | D17: BEBAN KLAIM
A18: 22 | B18: 13 | E18: Beban Klaim | F18: 115373687533 | G18: 8584555675 | H18: 75000000 | I18: 1271904226 | J18: 16228026979 | K18: =SUM(F18:J18) -> 141533174413 | L18: 6.2472544e+10 | M18: 6.790617e+08 | P18: 3.0437562e+10 | Q18: =N18+O18+P18 -> 3.0437562e+10 | R18: =SUM(L18:P18) -> 9.3589167e+10 | S18: =IF(K18=0,0,R18/K18) -> 0.66125251
A19: 24 | B19: 14 | E19: Kenaikan (Penurunan) Cadangan Klaim | F19: 3434033608 | G19: -2934113950 | H19: 51649426 | I19: 87275286 | J19: 8568198213 | K19: =SUM(F19:J19) -> 9207042583 | L19: 1.1979626e+10 | M19: -1.6420494e+09 | N19: 0 | O19: 0 | P19: 0 | Q19: -1.2086151e+10 | R19: =SUM(L19:Q19) -> -1.7485746e+09 | S19: =IF(K19=0,0,R19/K19) -> -0.18991708
A20: 32 | B20: 15 | E20: Pendapatan Subrogasi | F20: 38329244677 | G20: 6769350368 | H20: 22094493 | I20: 45084709 | J20: 16659323166 | K20: =SUM(F20:J20) -> 61825097413 | L20: 1.6502994e+10 | M20: 3.0560596e+09 | P20: 4.9699919e+09 | Q20: 4.2118817e+09 | R20: 2.3770936e+10 | S20: =IF(K20=0,0,R20/K20) -> 0.38448683
A21: 37 | B21: 16 | E21: Beban Komisi Netto | F21: 2396724198 | G21: 0 | H21: 54737539 | I21: 101532381 | J21: 1758987457 | K21: =SUM(F21:J21) -> 4311981575 | L21: 1.5270359e+09 | N21: 3107876.9 | O21: 2001225.9 | P21: 4.9840043e+08 | Q21: =N21+O21+P21 -> 5.0350954e+08 | R21: =SUM(L21:P21) -> 2.0305454e+09 | S21: =IF(K21=0,0,R21/K21) -> 0.47090773
C22: Y2 | E22: JUMLAH BEBAN KLAIM | F22: =F18+F19-F20-F21 -> 78081752266 | G22: =G18+G19-G20-G21 -> -1118908643 | H22: =H18+H19-H20-H21 -> 49817394 | I22: =I18+I19-I20-I21 -> 1212562422 | J22: =J18+J19-J20-J21 -> 6377914569 | K22: =K18+K19-K20-K21 -> 84603138008 | L22: =L18+L19-L20-L21 -> 5.6422139e+10 | M22: =M18+M19-M20-M21 -> -4.0190473e+09 | ... R22: =R18+R19-R20-R21 -> 6.6039112e+10 | S22: =IF(K22=0,0,R22/K22) -> 0.7805752
C24: X1 | D24: PENJAMINAN BERSIH | F24: =F15-F22 -> 75402755261 | G24: =G15-G22 -> 1118908643 | H24: =H15-H22 -> 2229257242 | I24: =I15-I22 -> 2574618029 | J24: =J15-J22 -> 1515834097 | K24: =K15-K22 -> 82841373272 | L24: =L15-L22 -> 2.0634256e+10 | M24: =M15-M22 -> 4.0190473e+09 | ... R24: =R15-R22 -> 3.5920592e+10 | S24: =IF(K24=0,0,R24/K24) -> 0.43360691
B26: 19 | C26: X1 | D26: PENDAPATAN INVESTASI BERSIH | F26: 0 | G26: 0 | H26: 0 | I26: 0 | J26: 0 | K26: 0
C28: X1 | D28: BEBAN USAHA
C29: X2 | E29: BEBAN KARYAWAN
A30: 94 | E30: Beban gaji karyawan | F30: 969596418 | G30: 0 | H30: 19882043 | I30: 25588713 | J30: 112590574 | K30: =SUM(F30:J30) -> 1127657748 | L30: 4.6431909e+08 | N30: 1630782.2 | O30: 5018695.7 | P30: 1.9680143e+08 | Q30: =N30+O30+P30 -> 2.034509e+08 | R30: =SUM(L30:P30) -> 667769998 | S30: =IF(K30=0,0,R30/K30) -> 0.59217435
A31: 95 | E31: Beban lembur karyawan | F31: 30358275 | G31: 0 | H31: 622511 | I31: 801188 | J31: 3525235 | K31: =SUM(F31:J31) -> 35307209 | L31: 11683487 | N31: 41094.828 | O31: 126468.41 | P31: 4959289.3 | Q31: =N31+O31+P31 -> 5126852.6 | R31: =SUM(L31:P31) -> 16810340 | S31: =IF(K31=0,0,R31/K31) -> 0.47611636
A32: 96 | E32: Beban asuransi kesehatan karyawan | F32: 156401572 | G32: 0 | H32: 3207090 | I32: 4127609 | J32: 18161518 | K32: =SUM(F32:J32) -> 181897789 | L32: 4104850 | N32: 11182.972 | O32: 34415.346 | P32: 1349551.7 | Q32: =N32+O32+P32 -> 1395150 | R32: =SUM(L32:P32) -> 5500000 | S32: =IF(K32=0,0,R32/K32) -> 0.030236761
A33: 97 | E33: Beban asuransi jiwa karyawan | F33: 7165646 | G33: 0 | H33: 146935 | I33: 189109 | J33: 832083 | K33: =SUM(F33:J33) -> 8333773
A34: 100 | E34: Beban dana pensiun | F34: 113572620 | G34: 0 | H34: 2328861 | I34: 2997306 | J34: 13188174 | K34: =SUM(F34:J34) -> 132086961
A35: 101 | E35: Beban kompensasi kinerja karyawan | F35: 1048226553 | G35: 0 | H35: 21494392 | I35: 27663848 | J35: 121721190 | K35: =SUM(F35:J35) -> 1219105983 | L35: 6.6022275e+08 | N35: 2323932.6 | O35: 7151850.6 | P35: 2.8045024e+08 | Q35: =N35+O35+P35 -> 2.8992602e+08 | R35: =SUM(L35:P35) -> 9.5014877e+08 | S35: =IF(K35=0,0,R35/K35) -> 0.7793816
A36: 102 | E36: Biaya jasa kini karyawan | F36: 0 | G36: 0 | H36: 0 | I36: 0 | J36: 0 | K36: =SUM(F36:J36) -> 0
A37: 103 | E37: Biaya jasa lalu karyawan | F37: 0 | G37: 0 | H37: 0 | I37: 0 | J37: 0 | K37: =SUM(F37:J37) -> 0
A38: 104 | E38: Bunga atas imbalan pasca kerja karyawan | F38: 171733351 | G38: 0 | H38: 3521475 | I38: 4532231 | J38: 19941861 | K38: =SUM(F38:J38) -> 199728918
A39: 105 | E39: Beban BPJS kesehatan karyawan | F39: 43586002 | G39: 0 | H39: 893752 | I39: 1150282 | J39: 5061253 | K39: =SUM(F39:J39) -> 50691289
A40: 106 | E40: Beban BPJS jaminan hari tua karyawan | F40: 61831059 | G40: 0 | H40: 1267876 | I40: 1631789 | J40: 7179889 | K40: =SUM(F40:J40) -> 71910613
A41: 107 | E41: Beban BPJS jaminan kecelakaan kerja dan jaminan kematian karyawan | F41: 8973711 | G41: 0 | H41: 184010 | I41: 236826 | J41: 1042037 | K41: =SUM(F41:J41) -> 10436584
A42: 108 | E42: Beban BPJS jaminan pensiun karyawan | F42: 20792745 | G42: 0 | H42: 426365 | I42: 548743 | J42: 2414476 | K42: =SUM(F42:J42) -> 24182329
A43: 109 | E43: Beban tunjangan hari raya karyawan | F43: 139469311 | G43: 0 | H43: 2859886 | I43: 3680748 | J43: 16195326 | K43: =SUM(F43:J43) -> 162205271 | L43: 1.9941911e+08 | N43: 731092.9 | O43: 2249922 | P43: 88227678 | Q43: =N43+O43+P43 -> 91208692 | R43: =SUM(L43:P43) -> 2.906278e+08 | S43: =IF(K43=0,0,R43/K43) -> 1.7917285
A44: 110 | E44: Beban tunjangan PPh 21 karyawan | F44: 1113365698 | G44: 0 | H44: 22830101 | I44: 29382941 | J44: 129285217 | K44: =SUM(F44:J44) -> 1294863957 | L44: 1.4698206e+08 | N44: 598838.17 | O44: 1842911 | P44: 72267288 | Q44: =N44+O44+P44 -> 74709037 | R44: =SUM(L44:P44) -> 2.2169109e+08 | S44: =IF(K44=0,0,R44/K44) -> 0.17120802
A45: 111 | E45: Beban tunjangan transportasi karyawan | F45: 29986962 | G45: 0 | H45: 614897 | I45: 791389 | J45: 3482118 | K45: =SUM(F45:J45) -> 34875366 | L45: 27794500 | N45: 97834.473 | O45: 301083.4 | P45: 11806582 | Q45: =N45+O45+P45 -> 12205500 | R45: =SUM(L45:P45) -> 40000000 | S45: =IF(K45=0,0,R45/K45) -> 1.1469414
A46: 112 | E46: Beban tunjangan jabatan | F46: 707805475 | G46: 0 | H46: 14513893 | I46: 18679762 | J46: 82191129 | K46: =SUM(F46:J46) -> 823190259 | L46: 3.0486689e+08 | N46: 1072887 | O46: 3301785.8 | P46: 1.2947511e+08 | Q46: =N46+O46+P46 -> 1.3384978e+08 | R46: =SUM(L46:P46) -> 4.3871667e+08 | S46: =IF(K46=0,0,R46/K46) -> 0.53294686
A47: 113 | E47: Beban tunjangan cuti besar | F47: 14274196 | G47: 0 | H47: 292699 | I47: 376712 | J47: 1657535 | K47: =SUM(F47:J47) -> 16601142
...

Sheet MADIUN
D1: PT JAMKRINDO KANWIL SURABAYA
D2: LABA RUGI RKA TAHUN 2026
D5: URAIAN | F5: KANCA MADIUN | L5: REALISASI KANCA MADIUN | S5: %
F6: KUR | G6: PEN | H6: KBG/SURETYSHIP | I6: KONSUMTIF | J6: PRODUKTIF | K6: TOTAL | L6: KUR | M6: PEN | N6: KBG/SURETYSHIP | O6: KONSUMTIF | P6: PRODUKTIF | Q6: NON KUR | R6: TOTAL | S6: %
F7: (a) | G7: (b) | H7: (c) | I7: (d) | J7: (e) | K7: (f) | L7: (g) | M7: (h) | N7: (i) | O7: (j) | P7: (k) | Q7: (l)=i+j+k | R7: (m) | S7: (n)=m/f
C9: X1 | D9: VOLUME | F9: 4373360134287 | G9: 0 | H9: 596979491872 | I9: 429946561406 | J9: 797362922440 | K9: =SUM(F9:J9) -> 6197649110005
C11: X2 | D11: PENDAPATAN PENJAMINAN
A12: 7 | B12: 8 | E12: Imbal Jasa Penjaminan Bruto | F12: 158130782723 | G12: 0 | H12: 1945528854 | I12: 4173244726 | J12: 18113455973 | K12: =SUM(F12:J12) -> 182363012276 | L12: 9.1722602e+10 | M12: 400000 | N12: 2.6199678e+08 | O12: 4.9517541e+08 | P12: 3.5692503e+10 | Q12: =N12+O12+P12 -> 3.6449675e+10 | R12: =SUM(L12:P12) -> 1.2817268e+11 | S12: =IF(K12=0,0,R12/K12) -> 0.7028436
A13: 12 | B13: 10 | E13: Restitusi penjaminan kredit | F13: 0 | G13: 0 | H13: 0 | I13: 0 | J13: 0 | K13: =SUM(F13:J13) -> 0
A14: 9 | B14: 9 | E14: Premi Penjaminan Ulang | F14: 14239056917 | G14: 0 | H14: 236222877 | I14: 622763053 | J14: 10794828562 | K14: =SUM(F14:J14) -> 25892871409 | L14: 9.8884319e+09 | N14: 25513308 | O14: 83337808 | P14: 4.521923e+09 | Q14: =N14+O14+P14 -> 4.6307741e+09 | R14: =SUM(L14:P14) -> 1.4519206e+10 | S14: =IF(K14=0,0,R14/K14) -> 0.56074144
C15: Y2 | E15: IMBAL JASA PENJAMINAN BERSIH | F15: =F12-F13-F14 -> 143891725806 | G15: =G12-G13-G14 -> 0 | H15: =H12-H13-H14 -> 1709305977 | I15: =I12-I13-I14 -> 3550481673 | J15: =J12-J13-J14 -> 7318627411 | K15: =K12-K13-K14 -> 156470140867 | L15: =L12-L13-L14 -> 8.183417e+10 | M15: =M12-M13-M14 -> 400000 | ... R15: =R12-R13-R14 -> 1.1365347e+11 | S15: =IF(K15=0,0,R15/K15) -> 0.72635884
C16: 22
C17: X2 | D17: BEBAN KLAIM
A18: 22 | B18: 13 | E18: Beban Klaim | F18: 114016714018 | G18: 862699986 | H18: 65000000 | I18: 681243458 | J18: 6355201369 | K18: =SUM(F18:J18) -> 121980858831 | L18: 2.4497858e+10 | M18: 1050000000 | P18: 2.5627569e+10 | Q18: =N18+O18+P18 -> 2.5627569e+10 | R18: =SUM(L18:P18) -> 5.1175427e+10 | S18: =IF(K18=0,0,R18/K18) -> 0.41953654
A19: 24 | B19: 14 | E19: Kenaikan (Penurunan) Cadangan Klaim | F19: 1226655107 | G19: -1050000000 | H19: 17700890 | I19: 0 | J19: 7006457653 | K19: =SUM(F19:J19) -> 7200813650 | L19: 37858644394 | M19: -1050000000 | N19: 0 | O19: 0 | P19: 0 | Q19: 11324597939 | R19: =SUM(L19:Q19) -> 48133242333 | S19: =IF(K19=0,0,R19/K19) -> 6.6844172
A20: 32 | B20: 15 | E20: Pendapatan Subrogasi | F20: 14796402193 | G20: 1780216045 | H20: 10434947 | I20: 21292932 | J20: 6451123904 | K20: =SUM(F20:J20) -> 23059470021 | L20: 9.4424025e+09 | M20: 42441861 | O20: 52995287 | P20: 3.499947e+09 | Q20: 3.1137272e+09 | R20: 1.2598572e+10 | S20: =IF(K20=0,0,R20/K20) -> 0.54635131
A21: 37 | B21: 16 | E21: Beban Komisi Netto | F21: 2246928935 | G21: 0 | H21: 41053154 | I21: 95186607 | J21: 1647108492 | K21: =SUM(F21:J21) -> 4030277188 | L21: 1.6269396e+09 | N21: 3896173.4 | O21: -8205515.9 | P21: 6.7255415e+08 | Q21: =N21+O21+P21 -> 6.6824481e+08 | R21: =SUM(L21:P21) -> 2.2951844e+09 | S21: =IF(K21=0,0,R21/K21) -> 0.56948549
C22: Y2 | E22: JUMLAH BEBAN KLAIM | F22: =F18+F19-F20-F21 -> 98200037997 | G22: =G18+G19-G20-G21 -> -1967516059 | H22: =H18+H19-H20-H21 -> 31212789 | I22: =I18+I19-I20-I21 -> 564763919 | J22: =J18+J19-J20-J21 -> 5263426626 | K22: =K18+K19-K20-K21 -> 102091925272 | L22: =L18+L19-L20-L21 -> 5.128716e+10 | M22: =M18+M19-M20-M21 -> -42441861 | ... R22: =R18+R19-R20-R21 -> 8.4414913e+10 | S22: =IF(K22=0,0,R22/K22) -> 0.82685201
C24: X1 | D24: PENJAMINAN BERSIH | F24: =F15-F22 -> 45691687809 | G24: =G15-G22 -> 1967516059 | H24: =H15-H22 -> 1678093188 | I24: =I15-I22 -> 2985717754 | J24: =J15-J22 -> 2055200785 | K24: =K15-K22 -> 54378215595 | L24: =L15-L22 -> 3.054701e+10 | M24: =M15-M22 -> 42841861 | ... R24: =R15-R22 -> 2.9238557e+10 | S24: =IF(K24=0,0,R24/K24) -> 0.5376888
B26: 19 | C26: X1 | D26: PENDAPATAN INVESTASI BERSIH | F26: 0 | G26: 0 | H26: 0 | I26: 0 | J26: 0 | K26: 0
C28: X1 | D28: BEBAN USAHA
C29: X2 | E29: BEBAN KARYAWAN
A30: 94 | E30: Beban gaji karyawan | F30: 1050396120 | G30: 0 | H30: 21538880 | I30: 27721105 | J30: 121973122 | K30: =SUM(F30:J30) -> 1221629227 | L30: 4.5728931e+08 | N30: 1438833.2 | O30: 2719403 | P30: 1.9601599e+08 | Q30: =N30+O30+P30 -> 2.0017423e+08 | R30: =SUM(L30:P30) -> 657463540 | S30: =IF(K30=0,0,R30/K30) -> 0.53818583
A31: 95 | E31: Beban lembur karyawan | F31: 20238850 | G31: 0 | H31: 415007 | I31: 534125 | J31: 2350157 | K31: =SUM(F31:J31) -> 23538139 | L31: 13343676 | N31: 37993.617 | O31: 71808.153 | P31: 5175969.2 | Q31: =N31+O31+P31 -> 5285771 | R31: =SUM(L31:P31) -> 18629447 | S31: =IF(K31=0,0,R31/K31) -> 0.79145794
A32: 96 | E32: Beban asuransi kesehatan karyawan | F32: 132339791 | G32: 0 | H32: 2713691 | I32: 3492592 | J32: 15367438 | K32: =SUM(F32:J32) -> 153913512 | L32: 6261080 | N32: 18249.515 | O32: 34491.686 | P32: 2486178.8 | Q32: =N32+O32+P32 -> 2538920 | R32: =SUM(L32:P32) -> 8800000 | S32: =IF(K32=0,0,R32/K32) -> 0.057174967
A33: 97 | E33: Beban asuransi jiwa karyawan | F33: 6063239 | G33: 0 | H33: 124330 | I33: 160016 | J33: 704070 | K33: =SUM(F33:J33) -> 7051655
A34: 100 | E34: Beban dana pensiun | F34: 96099909 | G34: 0 | H34: 1970575 | I34: 2536182 | J34: 11159224 | K34: =SUM(F34:J34) -> 111765890
